Workbook

Sheet Data_Entry
B1: NCD & CP — DAILY RATE ENTRY
B2: Enter one row per instrument per date. Yellow = manual entry. Blue columns auto-calculate from GSec_Benchmark & Portfolio_Summary sheets.
B4: Date | C4: Instrument Type | D4: Issuer Name | E4: ISIN / Ref | F4: Coupon (% p.a.) | G4: Freq (2=H/4=Q) | H4: Tenor (Years) | I4: Face Value (₹ Cr) | J4: Current Yield (% ) | K4: Clean Price (₹) | L4: Accrued Interest (₹) | M4: Gross Invoice Price | N4: Days to Maturity | O4: Current Mtm Value (₹ Cr)
B5: 2026-03-25 | C5: NCD | D5: HDFC Ltd | E5: INE001A08R39 | F5: 0.091 | G5: 2 | H5: 5 | I5: 100 | J5: 0.0915 | K5: 99.5
B6: 2026-03-25 | C6: NCD | D6: Power Finance Corp | E6: INE881A1DNN7 | F6: 0.082 | G6: 2 | H6: 3 | I6: 50 | J6: 0.083 | K6: 100.25
B7: 2026-03-25 | C7: CP | D7: Tata Capital Ltd | E7: INE851A14MZ6 | F7: 0.075 | G7: 4 | H7: 0.5 | I7: 25 | J7: 0.076 | K7: 99.1
L8: =IFERROR(J8+K8,J8) | M8: =IFERROR(IF(C8="CP",INT(G8*365),INT(G8*365)),"") | N8: =IFERROR(L8*H8/100,"")
L9: =IFERROR(J9+K9,J9) | M9: =IFERROR(IF(C9="CP",INT(G9*365),INT(G9*365)),"") | N9: =IFERROR(L9*H9/100,"")
L10: =IFERROR(J10+K10,J10) | M10: =IFERROR(IF(C10="CP",INT(G10*365),INT(G10*365)),"") | N10: =IFERROR(L10*H10/100,"")
L11: =IFERROR(J11+K11,J11) | M11: =IFERROR(IF(C11="CP",INT(G11*365),INT(G11*365)),"") | N11: =IFERROR(L11*H11/100,"")
L12: =IFERROR(J12+K12,J12) | M12: =IFERROR(IF(C12="CP",INT(G12*365),INT(G12*365)),"") | N12: =IFERROR(L12*H12/100,"")
L13: =IFERROR(J13+K13,J13) | M13: =IFERROR(IF(C13="CP",INT(G13*365),INT(G13*365)),"") | N13: =IFERROR(L13*H13/100,"")
L14: =IFERROR(J14+K14,J14) | M14: =IFERROR(IF(C14="CP",INT(G14*365),INT(G14*365)),"") | N14: =IFERROR(L14*H14/100,"")
L15: =IFERROR(J15+K15,J15) | M15: =IFERROR(IF(C15="CP",INT(G15*365),INT(G15*365)),"") | N15: =IFERROR(L15*H15/100,"")
L16: =IFERROR(J16+K16,J16) | M16: =IFERROR(IF(C16="CP",INT(G16*365),INT(G16*365)),"") | N16: =IFERROR(L16*H16/100,"")
L17: =IFERROR(J17+K17,J17) | M17: =IFERROR(IF(C17="CP",INT(G17*365),INT(G17*365)),"") | N17: =IFERROR(L17*H17/100,"")
L18: =IFERROR(J18+K18,J18) | M18: =IFERROR(IF(C18="CP",INT(G18*365),INT(G18*365)),"") | N18: =IFERROR(L18*H18/100,"")
L19: =IFERROR(J19+K19,J19) | M19: =IFERROR(IF(C19="CP",INT(G19*365),INT(G19*365)),"") | N19: =IFERROR(L19*H19/100,"")
... L264: =IFERROR(J264+K264,J264) | M264: =IFERROR(IF(C264="CP",INT(G264*365),INT(G264*365)),"") | N264: =IFERROR(L264*H264/100,"")
B265: PORTFOLIO TOTAL (₹ Cr) | H265: =SUM(H5:H264) | N265: =SUM(N5:N264)

Sheet Rates_DB
B1: RATES DATABASE — HISTORICAL LOG (AUTO-POPULATED)
B2: This sheet auto-records each day's entry. Do NOT edit. Use Data_Entry sheet for all inputs.
B4: Date | C4: Instrument | D4: Issuer | E4: ISIN | F4: Coupon | G4: Freq | H4: Tenor | I4: Face (₹ Cr) | J4: Yield (%) | K4: Price | L4: AI | M4: Invoice Price | N4: MTM (₹ Cr)
B6: ℹ To populate this database: run the Python script build_ncd_cp_tracker.py with --append flag, OR manually copy Data_Entry rows and Paste Special > Values here.

Sheet GSec_Benchmark
B1: G-SEC BENCHMARK YIELDS — MANUAL ENTRY (RBI / FBIL Data)
B2: Enter G-Sec yields by tenor daily from: https://fbil.org.in or RBI Database (DB). Spread calculations use 3Y, 5Y, 7Y, 10Y benchmarks.
B4: Date | C4: 1Y G-Sec | D4: 2Y G-Sec | E4: 3Y G-Sec | F4: 5Y G-Sec | G4: 7Y G-Sec | H4: 10Y G-Sec | I4: 15Y G-Sec | J4: 20Y G-Sec | K4: 25Y G-Sec | L4: 30Y G-Sec
B5: 2026-03-25 | C5: 0.067 | D5: 0.068 | E5: 0.069 | F5: 0.0695 | G5: 0.0705 | H5: 0.071 | I5: 0.073 | J5: 0.075 | K5: 0.076 | L5: 0.0765
B108: Spread = Instrument Yield - G-Sec Yield (nearest tenor). For CP (tenor < 1Y): compare vs 1Y G-Sec. For NCD 5Y: compare vs 5Y G-Sec.

Sheet Portfolio_Summary
B1: PORTFOLIO SUMMARY — LIVE
B2: Aggregated from Data_Entry sheet. Auto-updates when entries are changed.
B4: 1. PORTFOLIO BY INSTRUMENT TYPE
B5: Instrument | C5: Face Value (₹ Cr) | D5: MTM Value (₹ Cr) | E5: Wtd Avg Yield | F5: Wtd Avg Tenor
B6: NCD | C6: =SUMIFS(Data_Entry!H5:H265,Data_Entry!C5:C265,"NCD") | D6: =SUMIFS(Data_Entry!N5:N265,Data_Entry!C5:C265,"NCD") | E6: =IFERROR(SUMPRODUCT((Data_Entry!C5:C265="NCD")*Data_Entry!I5:I265*Data_Entry!H5:H265)/SUMIFS(Data_Entry!H5:H265,Data_Entry!C5:C265,"NCD"),"") | F6: =IFERROR(SUMPRODUCT((Data_Entry!C5:C265="NCD")*Data_Entry!G5:G265*Data_Entry!H5:H265)/SUMIFS(Data_Entry!H5:H265,Data_Entry!C5:C265,"NCD"),"")
B7: CP | C7: =SUMIFS(Data_Entry!H5:H265,Data_Entry!C5:C265,"CP") | D7: =SUMIFS(Data_Entry!N5:N265,Data_Entry!C5:C265,"CP") | E7: =IFERROR(SUMPRODUCT((Data_Entry!C5:C265="CP")*Data_Entry!I5:I265*Data_Entry!H5:H265)/SUMIFS(Data_Entry!H5:H265,Data_Entry!C5:C265,"CP"),"") | F7: =IFERROR(SUMPRODUCT((Data_Entry!C5:C265="CP")*Data_Entry!G5:G265*Data_Entry!H5:H265)/SUMIFS(Data_Entry!H5:H265,Data_Entry!C5:C265,"CP"),"")
B8: CD | C8: =SUMIFS(Data_Entry!H5:H265,Data_Entry!C5:C265,"CD") | D8: =SUMIFS(Data_Entry!N5:N265,Data_Entry!C5:C265,"CD") | E8: =IFERROR(SUMPRODUCT((Data_Entry!C5:C265="CD")*Data_Entry!I5:I265*Data_Entry!H5:H265)/SUMIFS(Data_Entry!H5:H265,Data_Entry!C5:C265,"CD"),"") | F8: =IFERROR(SUMPRODUCT((Data_Entry!C5:C265="CD")*Data_Entry!G5:G265*Data_Entry!H5:H265)/SUMIFS(Data_Entry!H5:H265,Data_Entry!C5:C265,"CD"),"")
B9: Bond | C9: =SUMIFS(Data_Entry!H5:H265,Data_Entry!C5:C265,"Bond") | D9: =SUMIFS(Data_Entry!N5:N265,Data_Entry!C5:C265,"Bond") | E9: =IFERROR(SUMPRODUCT((Data_Entry!C5:C265="Bond")*Data_Entry!I5:I265*Data_Entry!H5:H265)/SUMIFS(Data_Entry!H5:H265,Data_Entry!C5:C265,"Bond"),"") | F9: =IFERROR(SUMPRODUCT((Data_Entry!C5:C265="Bond")*Data_Entry!G5:G265*Data_Entry!H5:H265)/SUMIFS(Data_Entry!H5:H265,Data_Entry!C5:C265,"Bond"),"")
B10: Other | C10: =SUMIFS(Data_Entry!H5:H265,Data_Entry!C5:C265,"Other") | D10: =SUMIFS(Data_Entry!N5:N265,Data_Entry!C5:C265,"Other") | E10: =IFERROR(SUMPRODUCT((Data_Entry!C5:C265="Other")*Data_Entry!I5:I265*Data_Entry!H5:H265)/SUMIFS(Data_Entry!H5:H265,Data_Entry!C5:C265,"Other"),"") | F10: =IFERROR(SUMPRODUCT((Data_Entry!C5:C265="Other")*Data_Entry!G5:G265*Data_Entry!H5:H265)/SUMIFS(Data_Entry!H5:H265,Data_Entry!C5:C265,"Other"),"")
B11: TOTAL PORTFOLIO | C11: =SUM(C6:C10) | D11: =SUM(D6:D10) | E11: =IFERROR(SUMPRODUCT(Data_Entry!I5:I265*Data_Entry!H5:H265)/SUM(Data_Entry!H5:H265),"") | F11: =IFERROR(SUMPRODUCT(Data_Entry!G5:G265*Data_Entry!H5:H265)/SUM(Data_Entry!H5:H265),"")
B14: 2. PORTFOLIO BY ISSUER
B15: Issuer Name | C15: Instrument | D15: Face (₹ Cr) | E15: Yield (%) | F15: G-Sec Bench | G15: Spread (bp) | H15: MTM (₹ Cr)
B16: =IFERROR(INDEX(Data_Entry!D5:D265,MATCH(0,COUNTIF($B$16:B15,Data_Entry!D5:D265),0)+4),"")
B17: =IFERROR(INDEX(Data_Entry!D5:D265,MATCH(0,COUNTIF($B$16:B16,Data_Entry!D5:D265),0)+4),"")
B18: =IFERROR(INDEX(Data_Entry!D5:D265,MATCH(0,COUNTIF($B$16:B17,Data_Entry!D5:D265),0)+4),"")
B19: =IFERROR(INDEX(Data_Entry!D5:D265,MATCH(0,COUNTIF($B$16:B18,Data_Entry!D5:D265),0)+4),"")
B20: =IFERROR(INDEX(Data_Entry!D5:D265,MATCH(0,COUNTIF($B$16:B19,Data_Entry!D5:D265),0)+4),"")
B21: =IFERROR(INDEX(Data_Entry!D5:D265,MATCH(0,COUNTIF($B$16:B20,Data_Entry!D5:D265),0)+4),"")
B22: =IFERROR(INDEX(Data_Entry!D5:D265,MATCH(0,COUNTIF($B$16:B21,Data_Entry!D5:D265),0)+4),"")
B23: =IFERROR(INDEX(Data_Entry!D5:D265,MATCH(0,COUNTIF($B$16:B22,Data_Entry!D5:D265),0)+4),"")
B24: =IFERROR(INDEX(Data_Entry!D5:D265,MATCH(0,COUNTIF($B$16:B23,Data_Entry!D5:D265),0)+4),"")
B25: =IFERROR(INDEX(Data_Entry!D5:D265,MATCH(0,COUNTIF($B$16:B24,Data_Entry!D5:D265),0)+4),"")
B26: =IFERROR(INDEX(Data_Entry!D5:D265,MATCH(0,COUNTIF($B$16:B25,Data_Entry!D5:D265),0)+4),"")
B27: =IFERROR(INDEX(Data_Entry!D5:D265,MATCH(0,COUNTIF($B$16:B26,Data_Entry!D5:D265),0)+4),"")
B28: =IFERROR(INDEX(Data_Entry!D5:D265,MATCH(0,COUNTIF($B$16:B27,Data_Entry!D5:D265),0)+4),"")
B29: =IFERROR(INDEX(Data_Entry!D5:D265,MATCH(0,COUNTIF($B$16:B28,Data_Entry!D5:D265),0)+4),"")
B30: =IFERROR(INDEX(Data_Entry!D5:D265,MATCH(0,COUNTIF($B$16:B29,Data_Entry!D5:D265),0)+4),"")
B31: =IFERROR(INDEX(Data_Entry!D5:D265,MATCH(0,COUNTIF($B$16:B30,Data_Entry!D5:D265),0)+4),"")
B32: =IFERROR(INDEX(Data_Entry!D5:D265,MATCH(0,COUNTIF($B$16:B31,Data_Entry!D5:D265),0)+4),"")
B33: =IFERROR(INDEX(Data_Entry!D5:D265,MATCH(0,COUNTIF($B$16:B32,Data_Entry!D5:D265),0)+4),"")
B34: =IFERROR(INDEX(Data_Entry!D5:D265,MATCH(0,COUNTIF($B$16:B33,Data_Entry!D5:D265),0)+4),"")
B35: =IFERROR(INDEX(Data_Entry!D5:D265,MATCH(0,COUNTIF($B$16:B34,Data_Entry!D5:D265),0)+4),"")
B38: 3. PORTFOLIO DURATION & RISK METRICS
B39: Metric | C39: Value | D39: Formula / Notes
B40: Portfolio Modified Duration | C40: =IFERROR(SUMPRODUCT((Data_Entry!C5:C265)="NCD")*Data_Entry!G5:G265*Data_Entry!H5:H265)/SUMIFS(Data_Entry!H5:H265,Data_Entry!C5:C265,"NCD")/(1+Data_Entry!I5:I265),"Check data") | D40: Approx — assumes bullet NCD. For amortising, use actual schedule.
B41: Portfolio DV01 (₹ Cr per bp) | C41: =C40*SUM(Data_Entry!H5:H265)/10000 | D41: Price sensitivity per 1bp yield move
B42: Estimated MTM Δ per +100bp | C42: =-C40*SUM(Data_Entry!H5:H265)*0.01 | D42: Approx portfolio loss for 100bp rate rise
B43: Estimated MTM Δ per -100bp | C43: =C40*SUM(Data_Entry!H5:H265)*0.01 | D43: Approx portfolio gain for 100bp rate fall

Sheet MTM
B1: MARK-TO-MARKET (MTM) TRACKER
B2: Tracks daily MTM using latest prices vs cost/issue price. For unrealized gain/loss: MTM Value - Carrying Value.
B3: Date (Manual) | C3: Issuer | D3: Instrument | E3: Face Value (₹ Cr) | F3: Issue Price / Cost (₹) | G3: Current Clean Price (₹) | H3: MTM Value (₹ Cr) | I3: Unrealised G/L (₹ Cr) | J3: Unrealised G/L (%)
C4: =IFERROR(Data_Entry!D$5,"") | D4: =IFERROR(Data_Entry!C$5,"") | E4: =IFERROR(Data_Entry!H$5,"") | F4: =IFERROR(Data_Entry!L$5,"") | G4: =IFERROR(Data_Entry!J$5,"") | H4: =IFERROR(G4*E4/100,"") | I4: =IFERROR(H4-F4*E4/100,"") | J4: =IFERROR(I4/(F4*E4/100),"")
C5: =IFERROR(Data_Entry!D$6,"") | D5: =IFERROR(Data_Entry!C$6,"") | E5: =IFERROR(Data_Entry!H$6,"") | F5: =IFERROR(Data_Entry!L$6,"") | G5: =IFERROR(Data_Entry!J$6,"") | H5: =IFERROR(G5*E5/100,"") | I5: =IFERROR(H5-F5*E5/100,"") | J5: =IFERROR(I5/(F5*E5/100),"")
C6: =IFERROR(Data_Entry!D$7,"") | D6: =IFERROR(Data_Entry!C$7,"") | E6: =IFERROR(Data_Entry!H$7,"") | F6: =IFERROR(Data_Entry!L$7,"") | G6: =IFERROR(Data_Entry!J$7,"") | H6: =IFERROR(G6*E6/100,"") | I6: =IFERROR(H6-F6*E6/100,"") | J6: =IFERROR(I6/(F6*E6/100),"")
C7: =IFERROR(Data_Entry!D$8,"") | D7: =IFERROR(Data_Entry!C$8,"") | E7: =IFERROR(Data_Entry!H$8,"") | F7: =IFERROR(Data_Entry!L$8,"") | G7: =IFERROR(Data_Entry!J$8,"") | H7: =IFERROR(G7*E7/100,"") | I7: =IFERROR(H7-F7*E7/100,"") | J7: =IFERROR(I7/(F7*E7/100),"")
C8: =IFERROR(Data_Entry!D$9,"") | D8: =IFERROR(Data_Entry!C$9,"") | E8: =IFERROR(Data_Entry!H$9,"") | F8: =IFERROR(Data_Entry!L$9,"") | G8: =IFERROR(Data_Entry!J$9,"") | H8: =IFERROR(G8*E8/100,"") | I8: =IFERROR(H8-F8*E8/100,"") | J8: =IFERROR(I8/(F8*E8/100),"")
C9: =IFERROR(Data_Entry!D$10,"") | D9: =IFERROR(Data_Entry!C$10,"") | E9: =IFERROR(Data_Entry!H$10,"") | F9: =IFERROR(Data_Entry!L$10,"") | G9: =IFERROR(Data_Entry!J$10,"") | H9: =IFERROR(G9*E9/100,"") | I9: =IFERROR(H9-F9*E9/100,"") | J9: =IFERROR(I9/(F9*E9/100),"")
C10: =IFERROR(Data_Entry!D$11,"") | D10: =IFERROR(Data_Entry!C$11,"") | E10: =IFERROR(Data_Entry!H$11,"") | F10: =IFERROR(Data_Entry!L$11,"") | G10: =IFERROR(Data_Entry!J$11,"") | H10: =IFERROR(G10*E10/100,"") | I10: =IFERROR(H10-F10*E10/100,"") | J10: =IFERROR(I10/(F10*E10/100),"")
C11: =IFERROR(Data_Entry!D$12,"") | D11: =IFERROR(Data_Entry!C$12,"") | E11: =IFERROR(Data_Entry!H$12,"") | F11: =IFERROR(Data_Entry!L$12,"") | G11: =IFERROR(Data_Entry!J$12,"") | H11: =IFERROR(G11*E11/100,"") | I11: =IFERROR(H11-F11*E11/100,"") | J11: =IFERROR(I11/(F11*E11/100),"")
C12: =IFERROR(Data_Entry!D$13,"") | D12: =IFERROR(Data_Entry!C$13,"") | E12: =IFERROR(Data_Entry!H$13,"") | F12: =IFERROR(Data_Entry!L$13,"") | G12: =IFERROR(Data_Entry!J$13,"") | H12: =IFERROR(G12*E12/100,"") | I12: =IFERROR(H12-F12*E12/100,"") | J12: =IFERROR(I12/(F12*E12/100),"")
C13: =IFERROR(Data_Entry!D$14,"") | D13: =IFERROR(Data_Entry!C$14,"") | E13: =IFERROR(Data_Entry!H$14,"") | F13: =IFERROR(Data_Entry!L$14,"") | G13: =IFERROR(Data_Entry!J$14,"") | H13: =IFERROR(G13*E13/100,"") | I13: =IFERROR(H13-F13*E13/100,"") | J13: =IFERROR(I13/(F13*E13/100),"")
C14: =IFERROR(Data_Entry!D$15,"") | D14: =IFERROR(Data_Entry!C$15,"") | E14: =IFERROR(Data_Entry!H$15,"") | F14: =IFERROR(Data_Entry!L$15,"") | G14: =IFERROR(Data_Entry!J$15,"") | H14: =IFERROR(G14*E14/100,"") | I14: =IFERROR(H14-F14*E14/100,"") | J14: =IFERROR(I14/(F14*E14/100),"")
C15: =IFERROR(Data_Entry!D$16,"") | D15: =IFERROR(Data_Entry!C$16,"") | E15: =IFERROR(Data_Entry!H$16,"") | F15: =IFERROR(Data_Entry!L$16,"") | G15: =IFERROR(Data_Entry!J$16,"") | H15: =IFERROR(G15*E15/100,"") | I15: =IFERROR(H15-F15*E15/100,"") | J15: =IFERROR(I15/(F15*E15/100),"")
C16: =IFERROR(Data_Entry!D$17,"") | D16: =IFERROR(Data_Entry!C$17,"") | E16: =IFERROR(Data_Entry!H$17,"") | F16: =IFERROR(Data_Entry!L$17,"") | G16: =IFERROR(Data_Entry!J$17,"") | H16: =IFERROR(G16*E16/100,"") | I16: =IFERROR(H16-F16*E16/100,"") | J16: =IFERROR(I16/(F16*E16/100),"")
C17: =IFERROR(Data_Entry!D$18,"") | D17: =IFERROR(Data_Entry!C$18,"") | E17: =IFERROR(Data_Entry!H$18,"") | F17: =IFERROR(Data_Entry!L$18,"") | G17: =IFERROR(Data_Entry!J$18,"") | H17: =IFERROR(G17*E17/100,"") | I17: =IFERROR(H17-F17*E17/100,"") | J17: =IFERROR(I17/(F17*E17/100),"")
C18: =IFERROR(Data_Entry!D$19,"") | D18: =IFERROR(Data_Entry!C$19,"") | E18: =IFERROR(Data_Entry!H$19,"") | F18: =IFERROR(Data_Entry!L$19,"") | G18: =IFERROR(Data_Entry!J$19,"") | H18: =IFERROR(G18*E18/100,"") | I18: =IFERROR(H18-F18*E18/100,"") | J18: =IFERROR(I18/(F18*E18/100),"")
C19: =IFERROR(Data_Entry!D$20,"") | D19: =IFERROR(Data_Entry!C$20,"") | E19: =IFERROR(Data_Entry!H$20,"") | F19: =IFERROR(Data_Entry!L$20,"") | G19: =IFERROR(Data_Entry!J$20,"") | H19: =IFERROR(G19*E19/100,"") | I19: =IFERROR(H19-F19*E19/100,"") | J19: =IFERROR(I19/(F19*E19/100),"")
C20: =IFERROR(Data_Entry!D$21,"") | D20: =IFERROR(Data_Entry!C$21,"") | E20: =IFERROR(Data_Entry!H$21,"") | F20: =IFERROR(Data_Entry!L$21,"") | G20: =IFERROR(Data_Entry!J$21,"") | H20: =IFERROR(G20*E20/100,"") | I20: =IFERROR(H20-F20*E20/100,"") | J20: =IFERROR(I20/(F20*E20/100),"")
C21: =IFERROR(Data_Entry!D$22,"") | D21: =IFERROR(Data_Entry!C$22,"") | E21: =IFERROR(Data_Entry!H$22,"") | F21: =IFERROR(Data_Entry!L$22,"") | G21: =IFERROR(Data_Entry!J$22,"") | H21: =IFERROR(G21*E21/100,"") | I21: =IFERROR(H21-F21*E21/100,"") | J21: =IFERROR(I21/(F21*E21/100),"")
C22: =IFERROR(Data_Entry!D$23,"") | D22: =IFERROR(Data_Entry!C$23,"") | E22: =IFERROR(Data_Entry!H$23,"") | F22: =IFERROR(Data_Entry!L$23,"") | G22: =IFERROR(Data_Entry!J$23,"") | H22: =IFERROR(G22*E22/100,"") | I22: =IFERROR(H22-F22*E22/100,"") | J22: =IFERROR(I22/(F22*E22/100),"")
C23: =IFERROR(Data_Entry!D$24,"") | D23: =IFERROR(Data_Entry!C$24,"") | E23: =IFERROR(Data_Entry!H$24,"") | F23: =IFERROR(Data_Entry!L$24,"") | G23: =IFERROR(Data_Entry!J$24,"") | H23: =IFERROR(G23*E23/100,"") | I23: =IFERROR(H23-F23*E23/100,"") | J23: =IFERROR(I23/(F23*E23/100),"")
C24: =IFERROR(Data_Entry!D$25,"") | D24: =IFERROR(Data_Entry!C$25,"") | E24: =IFERROR(Data_Entry!H$25,"") | F24: =IFERROR(Data_Entry!L$25,"") | G24: =IFERROR(Data_Entry!J$25,"") | H24: =IFERROR(G24*E24/100,"") | I24: =IFERROR(H24-F24*E24/100,"") | J24: =IFERROR(I24/(F24*E24/100),"")
C25: =IFERROR(Data_Entry!D$26,"") | D25: =IFERROR(Data_Entry!C$26,"") | E25: =IFERROR(Data_Entry!H$26,"") | F25: =IFERROR(Data_Entry!L$26,"") | G25: =IFERROR(Data_Entry!J$26,"") | H25: =IFERROR(G25*E25/100,"") | I25: =IFERROR(H25-F25*E25/100,"") | J25: =IFERROR(I25/(F25*E25/100),"")
C26: =IFERROR(Data_Entry!D$27,"") | D26: =IFERROR(Data_Entry!C$27,"") | E26: =IFERROR(Data_Entry!H$27,"") | F26: =IFERROR(Data_Entry!L$27,"") | G26: =IFERROR(Data_Entry!J$27,"") | H26: =IFERROR(G26*E26/100,"") | I26: =IFERROR(H26-F26*E26/100,"") | J26: =IFERROR(I26/(F26*E26/100),"")
C27: =IFERROR(Data_Entry!D$28,"") | D27: =IFERROR(Data_Entry!C$28,"") | E27: =IFERROR(Data_Entry!H$28,"") | F27: =IFERROR(Data_Entry!L$28,"") | G27: =IFERROR(Data_Entry!J$28,"") | H27: =IFERROR(G27*E27/100,"") | I27: =IFERROR(H27-F27*E27/100,"") | J27: =IFERROR(I27/(F27*E27/100),"")
C28: =IFERROR(Data_Entry!D$29,"") | D28: =IFERROR(Data_Entry!C$29,"") | E28: =IFERROR(Data_Entry!H$29,"") | F28: =IFERROR(Data_Entry!L$29,"") | G28: =IFERROR(Data_Entry!J$29,"") | H28: =IFERROR(G28*E28/100,"") | I28: =IFERROR(H28-F28*E28/100,"") | J28: =IFERROR(I28/(F28*E28/100),"")
C29: =IFERROR(Data_Entry!D$30,"") | D29: =IFERROR(Data_Entry!C$30,"") | E29: =IFERROR(Data_Entry!H$30,"") | F29: =IFERROR(Data_Entry!L$30,"") | G29: =IFERROR(Data_Entry!J$30,"") | H29: =IFERROR(G29*E29/100,"") | I29: =IFERROR(H29-F29*E29/100,"") | J29: =IFERROR(I29/(F29*E29/100),"")
C30: =IFERROR(Data_Entry!D$31,"") | D30: =IFERROR(Data_Entry!C$31,"") | E30: =IFERROR(Data_Entry!H$31,"") | F30: =IFERROR(Data_Entry!L$31,"") | G30: =IFERROR(Data_Entry!J$31,"") | H30: =IFERROR(G30*E30/100,"") | I30: =IFERROR(H30-F30*E30/100,"") | J30: =IFERROR(I30/(F30*E30/100),"")
C31: =IFERROR(Data_Entry!D$32,"") | D31: =IFERROR(Data_Entry!C$32,"") | E31: =IFERROR(Data_Entry!H$32,"") | F31: =IFERROR(Data_Entry!L$32,"") | G31: =IFERROR(Data_Entry!J$32,"") | H31: =IFERROR(G31*E31/100,"") | I31: =IFERROR(H31-F31*E31/100,"") | J31: =IFERROR(I31/(F31*E31/100),"")
C32: =IFERROR(Data_Entry!D$33,"") | D32: =IFERROR(Data_Entry!C$33,"") | E32: =IFERROR(Data_Entry!H$33,"") | F32: =IFERROR(Data_Entry!L$33,"") | G32: =IFERROR(Data_Entry!J$33,"") | H32: =IFERROR(G32*E32/100,"") | I32: =IFERROR(H32-F32*E32/100,"") | J32: =IFERROR(I32/(F32*E32/100),"")
C33: =IFERROR(Data_Entry!D$34,"") | D33: =IFERROR(Data_Entry!C$34,"") | E33: =IFERROR(Data_Entry!H$34,"") | F33: =IFERROR(Data_Entry!L$34,"") | G33: =IFERROR(Data_Entry!J$34,"") | H33: =IFERROR(G33*E33/100,"") | I33: =IFERROR(H33-F33*E33/100,"") | J33: =IFERROR(I33/(F33*E33/100),"")
C34: =IFERROR(Data_Entry!D$35,"") | D34: =IFERROR(Data_Entry!C$35,"") | E34: =IFERROR(Data_Entry!H$35,"") | F34: =IFERROR(Data_Entry!L$35,"") | G34: =IFERROR(Data_Entry!J$35,"") | H34: =IFERROR(G34*E34/100,"") | I34: =IFERROR(H34-F34*E34/100,"") | J34: =IFERROR(I34/(F34*E34/100),"")
C35: =IFERROR(Data_Entry!D$36,"") | D35: =IFERROR(Data_Entry!C$36,"") | E35: =IFERROR(Data_Entry!H$36,"") | F35: =IFERROR(Data_Entry!L$36,"") | G35: =IFERROR(Data_Entry!J$36,"") | H35: =IFERROR(G35*E35/100,"") | I35: =IFERROR(H35-F35*E35/100,"") | J35: =IFERROR(I35/(F35*E35/100),"")
C36: =IFERROR(Data_Entry!D$37,"") | D36: =IFERROR(Data_Entry!C$37,"") | E36: =IFERROR(Data_Entry!H$37,"") | F36: =IFERROR(Data_Entry!L$37,"") | G36: =IFERROR(Data_Entry!J$37,"") | H36: =IFERROR(G36*E36/100,"") | I36: =IFERROR(H36-F36*E36/100,"") | J36: =IFERROR(I36/(F36*E36/100),"")
C37: =IFERROR(Data_Entry!D$38,"") | D37: =IFERROR(Data_Entry!C$38,"") | E37: =IFERROR(Data_Entry!H$38,"") | F37: =IFERROR(Data_Entry!L$38,"") | G37: =IFERROR(Data_Entry!J$38,"") | H37: =IFERROR(G37*E37/100,"") | I37: =IFERROR(H37-F37*E37/100,"") | J37: =IFERROR(I37/(F37*E37/100),"")
C38: =IFERROR(Data_Entry!D$39,"") | D38: =IFERROR(Data_Entry!C$39,"") | E38: =IFERROR(Data_Entry!H$39,"") | F38: =IFERROR(Data_Entry!L$39,"") | G38: =IFERROR(Data_Entry!J$39,"") | H38: =IFERROR(G38*E38/100,"") | I38: =IFERROR(H38-F38*E38/100,"") | J38: =IFERROR(I38/(F38*E38/100),"")
C39: =IFERROR(Data_Entry!D$40,"") | D39: =IFERROR(Data_Entry!C$40,"") | E39: =IFERROR(Data_Entry!H$40,"") | F39: =IFERROR(Data_Entry!L$40,"") | G39: =IFERROR(Data_Entry!J$40,"") | H39: =IFERROR(G39*E39/100,"") | I39: =IFERROR(H39-F39*E39/100,"") | J39: =IFERROR(I39/(F39*E39/100),"")
C40: =IFERROR(Data_Entry!D$41,"") | D40: =IFERROR(Data_Entry!C$41,"") | E40: =IFERROR(Data_Entry!H$41,"") | F40: =IFERROR(Data_Entry!L$41,"") | G40: =IFERROR(Data_Entry!J$41,"") | H40: =IFERROR(G40*E40/100,"") | I40: =IFERROR(H40-F40*E40/100,"") | J40: =IFERROR(I40/(F40*E40/100),"")
...

Sheet Alerts
B1: ALERTS & THRESHOLD MONITORING
B2: Set yield/spread/basis-point thresholds below. Enter trigger values in YELLOW. Alerts generate when current > threshold (RED = breach).
B4: YIELD BREACHES
B5: Alert Name | C5: Metric | D5: Direction | E5: Threshold (Enter) | F5: Current Value | G5: Status
B6: Max portfolio yield drop | C6: Yield | D6: Below | E6: 0.05 | G6: =IF(E6="","",IF(D6="Above",IF(F6>E6,"⚠ BREACH","✅ OK"),IF(F6<E6,"⚠ BREACH","✅ OK")))
B7: Max portfolio yield spike | C7: Yield | D7: Above | E7: 0.12 | G7: =IF(E7="","",IF(D7="Above",IF(F7>E7,"⚠ BREACH","✅ OK"),IF(F7<E7,"⚠ BREACH","✅ OK")))
B9: SPREAD ALERTS
B10: Alert Name | C10: Metric | D10: Direction | E10: Threshold (Enter) | F10: Current Value | G10: Status
B11: NCD spread over G-Sec (max) | C11: Spread vs G-Sec | D11: Above | E11: 200 | G11: =IF(E11="","",IF(D11="Above",IF(F11>E11,"⚠ BREACH","✅ OK"),IF(F11<E11,"⚠ BREACH","✅ OK")))
B12: CP spread over G-Sec (max) | C12: Spread vs G-Sec | D12: Above | E12: 150 | G12: =IF(E12="","",IF(D12="Above",IF(F12>E12,"⚠ BREACH","✅ OK"),IF(F12<E12,"⚠ BREACH","✅ OK")))
B14: MTM ALERTS
B15: Alert Name | C15: Metric | D15: Direction | E15: Threshold (Enter) | F15: Current Value | G15: Status
B16: Daily MTM drop (₹ Cr) | C16: MTM Unrealised G/L | D16: Below | E16: -5 | G16: =IF(E16="","",IF(D16="Above",IF(F16>E16,"⚠ BREACH","✅ OK"),IF(F16<E16,"⚠ BREACH","✅ OK")))
B17: Daily MTM gain (₹ Cr) | C17: MTM Unrealised G/L | D17: Above | E17: 5 | G17: =IF(E17="","",IF(D17="Above",IF(F17>E17,"⚠ BREACH","✅ OK"),IF(F17<E17,"⚠ BREACH","✅ OK")))
B19: CONCENTRATION ALERTS
B20: Alert Name | C20: Metric | D20: Direction | E20: Threshold (Enter) | F20: Current Value | G20: Status
B21: Single issuer max exposure (₹ Cr) | C21: Issuer Face Value | D21: Above | E21: 50 | G21: =IF(E21="","",IF(D21="Above",IF(F21>E21,"⚠ BREACH","✅ OK"),IF(F21<E21,"⚠ BREACH","✅ OK")))
B22: Single instrument max (₹ Cr) | C22: Face Value | D22: Above | E22: 100 | G22: =IF(E22="","",IF(D22="Above",IF(F22>E22,"⚠ BREACH","✅ OK"),IF(F22<E22,"⚠ BREACH","✅ OK")))
B24: ⚠ BREACH = Threshold crossed — review needed | ✅ OK = Within thresholds
