Workbook

Sheet Inputs
B1: TERM LOAN / BORROWING — DURATION CALCULATOR
B2: Macaulay Duration | Modified Duration | DV01 | Convexity | Price Sensitivity
B4: LOAN PARAMETERS
B6: Principal (₹ Cr) | C6: 100 | D6: Loan notional
B7: Coupon Rate (% p.a.) | C7: 9.1 | D7: Nominal coupon — changes to coupon freq below
B8: Frequency (1=Yr, 2=Half, 4=Qtr) | C8: 2 | D8: Compounding periods per year
B9: Yield / YTM (% p.a.) | C9: 8.75 | D9: Market yield used for PV discounting
B10: Tenor (Years) | C10: 7 | D10: Loan maturity in years — can be fractional
B11: Start Date | C11: 46113 | D11: Loan drawdown / first coupon date
B12: Amortisation Type | C12: Bullet | D12: Bullet OR amortising (enter exactly: Bullet / Full / Partial)
B13: Partial Amort Rate (% principal/yr) | C13: 0 | D13: Only used if Type = Partial — % of principal repaid per year
B15: KEY OUTPUTS (LIVE — see Results Sheet)
B17: Macaulay Duration (Years) | C17: ='Results'!C8
B18: Modified Duration (Years) | C18: ='Results'!C9
B19: DV01 (₹ Cr per bp) | C19: ='Results'!C10
B20: Convexity | C20: ='Results'!C11
B21: Price per ₹100 face (₹) | C21: ='Results'!C12
B22: Modified Duration × Face Value | C22: ='Results'!C13
B23: Approx Price Change per 100bp up (₹ Cr) | C23: ='Results'!C14
B24: Approx Price Change per 100bp down (₹ Cr) | C24: ='Results'!C15
B26: NOTE: Change inputs (yellow cells) — all outputs update automatically. VBA What-If button on 'What-If' sheet runs Monte Carlo yield scenario simulation.

Sheet Cash Flows
B1: CASH FLOW SCHEDULE & DURATION CALCULATION | K1: 125
K2: 5
B3: Period | C3: Date | D3: Coupon (₹ Cr) | E3: Principal (₹ Cr) | F3: Total CF (₹ Cr) | G3: PV Factor | H3: PV of CF (₹ Cr) | I3: Weight × Time | K3: 120
B4: ← From Inputs sheet: | C4: Frequency: | D4: =Inputs!C8 | E4: Yield: | F4: =Inputs!C9 | G4: Tenor: | H4: =Inputs!C10
B5: 1 | C5: =DATE(YEAR(Inputs!C11),MONTH(Inputs!C11)+(1-1)*(12/Inputs!C8),DAY(Inputs!C11)) | D5: =IF(1<=Inputs!C10*Inputs!C8,Inputs!C6*Inputs!C7/Inputs!C8,0) | E5: =IF(Inputs!C12="Bullet",IF(1=Inputs!C10*Inputs!C8,IF(Inputs!C12="Bullet",Inputs!C6,0),0),IF(Inputs!C12="Full",IF(1<=Inputs!C10*Inputs!C8,Inputs!C6/(Inputs!C10*Inputs!C8),0),IF(1<=Inputs!C10*Inputs!C8,MAX(Inputs!C6*Inputs!C13/Inputs!C8-SUM($D$5:$D4),0),0))) | F5: =D5+E5 | G5: =IFERROR(1/(1+Inputs!C9/Inputs!C8)^1,"") | H5: =F5*G5
B6: 2 | C6: =DATE(YEAR(Inputs!C11),MONTH(Inputs!C11)+(2-1)*(12/Inputs!C8),DAY(Inputs!C11)) | D6: =IF(2<=Inputs!C10*Inputs!C8,Inputs!C6*Inputs!C7/Inputs!C8,0) | E6: =IF(Inputs!C12="Bullet",IF(2=Inputs!C10*Inputs!C8,IF(Inputs!C12="Bullet",Inputs!C6,0),0),IF(Inputs!C12="Full",IF(2<=Inputs!C10*Inputs!C8,Inputs!C6/(Inputs!C10*Inputs!C8),0),IF(2<=Inputs!C10*Inputs!C8,MAX(Inputs!C6*Inputs!C13/Inputs!C8-SUM($D$5:$D5),0),0))) | F6: =D6+E6 | G6: =IFERROR(1/(1+Inputs!C9/Inputs!C8)^2,"") | H6: =F6*G6
B7: 3 | C7: =DATE(YEAR(Inputs!C11),MONTH(Inputs!C11)+(3-1)*(12/Inputs!C8),DAY(Inputs!C11)) | D7: =IF(3<=Inputs!C10*Inputs!C8,Inputs!C6*Inputs!C7/Inputs!C8,0) | E7: =IF(Inputs!C12="Bullet",IF(3=Inputs!C10*Inputs!C8,IF(Inputs!C12="Bullet",Inputs!C6,0),0),IF(Inputs!C12="Full",IF(3<=Inputs!C10*Inputs!C8,Inputs!C6/(Inputs!C10*Inputs!C8),0),IF(3<=Inputs!C10*Inputs!C8,MAX(Inputs!C6*Inputs!C13/Inputs!C8-SUM($D$5:$D6),0),0))) | F7: =D7+E7 | G7: =IFERROR(1/(1+Inputs!C9/Inputs!C8)^3,"") | H7: =F7*G7
B8: 4 | C8: =DATE(YEAR(Inputs!C11),MONTH(Inputs!C11)+(4-1)*(12/Inputs!C8),DAY(Inputs!C11)) | D8: =IF(4<=Inputs!C10*Inputs!C8,Inputs!C6*Inputs!C7/Inputs!C8,0) | E8: =IF(Inputs!C12="Bullet",IF(4=Inputs!C10*Inputs!C8,IF(Inputs!C12="Bullet",Inputs!C6,0),0),IF(Inputs!C12="Full",IF(4<=Inputs!C10*Inputs!C8,Inputs!C6/(Inputs!C10*Inputs!C8),0),IF(4<=Inputs!C10*Inputs!C8,MAX(Inputs!C6*Inputs!C13/Inputs!C8-SUM($D$5:$D7),0),0))) | F8: =D8+E8 | G8: =IFERROR(1/(1+Inputs!C9/Inputs!C8)^4,"") | H8: =F8*G8
B9: 5 | C9: =DATE(YEAR(Inputs!C11),MONTH(Inputs!C11)+(5-1)*(12/Inputs!C8),DAY(Inputs!C11)) | D9: =IF(5<=Inputs!C10*Inputs!C8,Inputs!C6*Inputs!C7/Inputs!C8,0) | E9: =IF(Inputs!C12="Bullet",IF(5=Inputs!C10*Inputs!C8,IF(Inputs!C12="Bullet",Inputs!C6,0),0),IF(Inputs!C12="Full",IF(5<=Inputs!C10*Inputs!C8,Inputs!C6/(Inputs!C10*Inputs!C8),0),IF(5<=Inputs!C10*Inputs!C8,MAX(Inputs!C6*Inputs!C13/Inputs!C8-SUM($D$5:$D8),0),0))) | F9: =D9+E9 | G9: =IFERROR(1/(1+Inputs!C9/Inputs!C8)^5,"") | H9: =F9*G9
B10: 6 | C10: =DATE(YEAR(Inputs!C11),MONTH(Inputs!C11)+(6-1)*(12/Inputs!C8),DAY(Inputs!C11)) | D10: =IF(6<=Inputs!C10*Inputs!C8,Inputs!C6*Inputs!C7/Inputs!C8,0) | E10: =IF(Inputs!C12="Bullet",IF(6=Inputs!C10*Inputs!C8,IF(Inputs!C12="Bullet",Inputs!C6,0),0),IF(Inputs!C12="Full",IF(6<=Inputs!C10*Inputs!C8,Inputs!C6/(Inputs!C10*Inputs!C8),0),IF(6<=Inputs!C10*Inputs!C8,MAX(Inputs!C6*Inputs!C13/Inputs!C8-SUM($D$5:$D9),0),0))) | F10: =D10+E10 | G10: =IFERROR(1/(1+Inputs!C9/Inputs!C8)^6,"") | H10: =F10*G10
B11: 7 | C11: =DATE(YEAR(Inputs!C11),MONTH(Inputs!C11)+(7-1)*(12/Inputs!C8),DAY(Inputs!C11)) | D11: =IF(7<=Inputs!C10*Inputs!C8,Inputs!C6*Inputs!C7/Inputs!C8,0) | E11: =IF(Inputs!C12="Bullet",IF(7=Inputs!C10*Inputs!C8,IF(Inputs!C12="Bullet",Inputs!C6,0),0),IF(Inputs!C12="Full",IF(7<=Inputs!C10*Inputs!C8,Inputs!C6/(Inputs!C10*Inputs!C8),0),IF(7<=Inputs!C10*Inputs!C8,MAX(Inputs!C6*Inputs!C13/Inputs!C8-SUM($D$5:$D10),0),0))) | F11: =D11+E11 | G11: =IFERROR(1/(1+Inputs!C9/Inputs!C8)^7,"") | H11: =F11*G11
B12: 8 | C12: =DATE(YEAR(Inputs!C11),MONTH(Inputs!C11)+(8-1)*(12/Inputs!C8),DAY(Inputs!C11)) | D12: =IF(8<=Inputs!C10*Inputs!C8,Inputs!C6*Inputs!C7/Inputs!C8,0) | E12: =IF(Inputs!C12="Bullet",IF(8=Inputs!C10*Inputs!C8,IF(Inputs!C12="Bullet",Inputs!C6,0),0),IF(Inputs!C12="Full",IF(8<=Inputs!C10*Inputs!C8,Inputs!C6/(Inputs!C10*Inputs!C8),0),IF(8<=Inputs!C10*Inputs!C8,MAX(Inputs!C6*Inputs!C13/Inputs!C8-SUM($D$5:$D11),0),0))) | F12: =D12+E12 | G12: =IFERROR(1/(1+Inputs!C9/Inputs!C8)^8,"") | H12: =F12*G12
B13: 9 | C13: =DATE(YEAR(Inputs!C11),MONTH(Inputs!C11)+(9-1)*(12/Inputs!C8),DAY(Inputs!C11)) | D13: =IF(9<=Inputs!C10*Inputs!C8,Inputs!C6*Inputs!C7/Inputs!C8,0) | E13: =IF(Inputs!C12="Bullet",IF(9=Inputs!C10*Inputs!C8,IF(Inputs!C12="Bullet",Inputs!C6,0),0),IF(Inputs!C12="Full",IF(9<=Inputs!C10*Inputs!C8,Inputs!C6/(Inputs!C10*Inputs!C8),0),IF(9<=Inputs!C10*Inputs!C8,MAX(Inputs!C6*Inputs!C13/Inputs!C8-SUM($D$5:$D12),0),0))) | F13: =D13+E13 | G13: =IFERROR(1/(1+Inputs!C9/Inputs!C8)^9,"") | H13: =F13*G13
B14: 10 | C14: =DATE(YEAR(Inputs!C11),MONTH(Inputs!C11)+(10-1)*(12/Inputs!C8),DAY(Inputs!C11)) | D14: =IF(10<=Inputs!C10*Inputs!C8,Inputs!C6*Inputs!C7/Inputs!C8,0) | E14: =IF(Inputs!C12="Bullet",IF(10=Inputs!C10*Inputs!C8,IF(Inputs!C12="Bullet",Inputs!C6,0),0),IF(Inputs!C12="Full",IF(10<=Inputs!C10*Inputs!C8,Inputs!C6/(Inputs!C10*Inputs!C8),0),IF(10<=Inputs!C10*Inputs!C8,MAX(Inputs!C6*Inputs!C13/Inputs!C8-SUM($D$5:$D13),0),0))) | F14: =D14+E14 | G14: =IFERROR(1/(1+Inputs!C9/Inputs!C8)^10,"") | H14: =F14*G14
B15: 11 | C15: =DATE(YEAR(Inputs!C11),MONTH(Inputs!C11)+(11-1)*(12/Inputs!C8),DAY(Inputs!C11)) | D15: =IF(11<=Inputs!C10*Inputs!C8,Inputs!C6*Inputs!C7/Inputs!C8,0) | E15: =IF(Inputs!C12="Bullet",IF(11=Inputs!C10*Inputs!C8,IF(Inputs!C12="Bullet",Inputs!C6,0),0),IF(Inputs!C12="Full",IF(11<=Inputs!C10*Inputs!C8,Inputs!C6/(Inputs!C10*Inputs!C8),0),IF(11<=Inputs!C10*Inputs!C8,MAX(Inputs!C6*Inputs!C13/Inputs!C8-SUM($D$5:$D14),0),0))) | F15: =D15+E15 | G15: =IFERROR(1/(1+Inputs!C9/Inputs!C8)^11,"") | H15: =F15*G15
B16: 12 | C16: =DATE(YEAR(Inputs!C11),MONTH(Inputs!C11)+(12-1)*(12/Inputs!C8),DAY(Inputs!C11)) | D16: =IF(12<=Inputs!C10*Inputs!C8,Inputs!C6*Inputs!C7/Inputs!C8,0) | E16: =IF(Inputs!C12="Bullet",IF(12=Inputs!C10*Inputs!C8,IF(Inputs!C12="Bullet",Inputs!C6,0),0),IF(Inputs!C12="Full",IF(12<=Inputs!C10*Inputs!C8,Inputs!C6/(Inputs!C10*Inputs!C8),0),IF(12<=Inputs!C10*Inputs!C8,MAX(Inputs!C6*Inputs!C13/Inputs!C8-SUM($D$5:$D15),0),0))) | F16: =D16+E16 | G16: =IFERROR(1/(1+Inputs!C9/Inputs!C8)^12,"") | H16: =F16*G16
B17: 13 | C17: =DATE(YEAR(Inputs!C11),MONTH(Inputs!C11)+(13-1)*(12/Inputs!C8),DAY(Inputs!C11)) | D17: =IF(13<=Inputs!C10*Inputs!C8,Inputs!C6*Inputs!C7/Inputs!C8,0) | E17: =IF(Inputs!C12="Bullet",IF(13=Inputs!C10*Inputs!C8,IF(Inputs!C12="Bullet",Inputs!C6,0),0),IF(Inputs!C12="Full",IF(13<=Inputs!C10*Inputs!C8,Inputs!C6/(Inputs!C10*Inputs!C8),0),IF(13<=Inputs!C10*Inputs!C8,MAX(Inputs!C6*Inputs!C13/Inputs!C8-SUM($D$5:$D16),0),0))) | F17: =D17+E17 | G17: =IFERROR(1/(1+Inputs!C9/Inputs!C8)^13,"") | H17: =F17*G17
B18: 14 | C18: =DATE(YEAR(Inputs!C11),MONTH(Inputs!C11)+(14-1)*(12/Inputs!C8),DAY(Inputs!C11)) | D18: =IF(14<=Inputs!C10*Inputs!C8,Inputs!C6*Inputs!C7/Inputs!C8,0) | E18: =IF(Inputs!C12="Bullet",IF(14=Inputs!C10*Inputs!C8,IF(Inputs!C12="Bullet",Inputs!C6,0),0),IF(Inputs!C12="Full",IF(14<=Inputs!C10*Inputs!C8,Inputs!C6/(Inputs!C10*Inputs!C8),0),IF(14<=Inputs!C10*Inputs!C8,MAX(Inputs!C6*Inputs!C13/Inputs!C8-SUM($D$5:$D17),0),0))) | F18: =D18+E18 | G18: =IFERROR(1/(1+Inputs!C9/Inputs!C8)^14,"") | H18: =F18*G18
B19: 15 | C19: =DATE(YEAR(Inputs!C11),MONTH(Inputs!C11)+(15-1)*(12/Inputs!C8),DAY(Inputs!C11)) | D19: =IF(15<=Inputs!C10*Inputs!C8,Inputs!C6*Inputs!C7/Inputs!C8,0) | E19: =IF(Inputs!C12="Bullet",IF(15=Inputs!C10*Inputs!C8,IF(Inputs!C12="Bullet",Inputs!C6,0),0),IF(Inputs!C12="Full",IF(15<=Inputs!C10*Inputs!C8,Inputs!C6/(Inputs!C10*Inputs!C8),0),IF(15<=Inputs!C10*Inputs!C8,MAX(Inputs!C6*Inputs!C13/Inputs!C8-SUM($D$5:$D18),0),0))) | F19: =D19+E19 | G19: =IFERROR(1/(1+Inputs!C9/Inputs!C8)^15,"") | H19: =F19*G19
B20: 16 | C20: =DATE(YEAR(Inputs!C11),MONTH(Inputs!C11)+(16-1)*(12/Inputs!C8),DAY(Inputs!C11)) | D20: =IF(16<=Inputs!C10*Inputs!C8,Inputs!C6*Inputs!C7/Inputs!C8,0) | E20: =IF(Inputs!C12="Bullet",IF(16=Inputs!C10*Inputs!C8,IF(Inputs!C12="Bullet",Inputs!C6,0),0),IF(Inputs!C12="Full",IF(16<=Inputs!C10*Inputs!C8,Inputs!C6/(Inputs!C10*Inputs!C8),0),IF(16<=Inputs!C10*Inputs!C8,MAX(Inputs!C6*Inputs!C13/Inputs!C8-SUM($D$5:$D19),0),0))) | F20: =D20+E20 | G20: =IFERROR(1/(1+Inputs!C9/Inputs!C8)^16,"") | H20: =F20*G20
B21: 17 | C21: =DATE(YEAR(Inputs!C11),MONTH(Inputs!C11)+(17-1)*(12/Inputs!C8),DAY(Inputs!C11)) | D21: =IF(17<=Inputs!C10*Inputs!C8,Inputs!C6*Inputs!C7/Inputs!C8,0) | E21: =IF(Inputs!C12="Bullet",IF(17=Inputs!C10*Inputs!C8,IF(Inputs!C12="Bullet",Inputs!C6,0),0),IF(Inputs!C12="Full",IF(17<=Inputs!C10*Inputs!C8,Inputs!C6/(Inputs!C10*Inputs!C8),0),IF(17<=Inputs!C10*Inputs!C8,MAX(Inputs!C6*Inputs!C13/Inputs!C8-SUM($D$5:$D20),0),0))) | F21: =D21+E21 | G21: =IFERROR(1/(1+Inputs!C9/Inputs!C8)^17,"") | H21: =F21*G21
B22: 18 | C22: =DATE(YEAR(Inputs!C11),MONTH(Inputs!C11)+(18-1)*(12/Inputs!C8),DAY(Inputs!C11)) | D22: =IF(18<=Inputs!C10*Inputs!C8,Inputs!C6*Inputs!C7/Inputs!C8,0) | E22: =IF(Inputs!C12="Bullet",IF(18=Inputs!C10*Inputs!C8,IF(Inputs!C12="Bullet",Inputs!C6,0),0),IF(Inputs!C12="Full",IF(18<=Inputs!C10*Inputs!C8,Inputs!C6/(Inputs!C10*Inputs!C8),0),IF(18<=Inputs!C10*Inputs!C8,MAX(Inputs!C6*Inputs!C13/Inputs!C8-SUM($D$5:$D21),0),0))) | F22: =D22+E22 | G22: =IFERROR(1/(1+Inputs!C9/Inputs!C8)^18,"") | H22: =F22*G22
B23: 19 | C23: =DATE(YEAR(Inputs!C11),MONTH(Inputs!C11)+(19-1)*(12/Inputs!C8),DAY(Inputs!C11)) | D23: =IF(19<=Inputs!C10*Inputs!C8,Inputs!C6*Inputs!C7/Inputs!C8,0) | E23: =IF(Inputs!C12="Bullet",IF(19=Inputs!C10*Inputs!C8,IF(Inputs!C12="Bullet",Inputs!C6,0),0),IF(Inputs!C12="Full",IF(19<=Inputs!C10*Inputs!C8,Inputs!C6/(Inputs!C10*Inputs!C8),0),IF(19<=Inputs!C10*Inputs!C8,MAX(Inputs!C6*Inputs!C13/Inputs!C8-SUM($D$5:$D22),0),0))) | F23: =D23+E23 | G23: =IFERROR(1/(1+Inputs!C9/Inputs!C8)^19,"") | H23: =F23*G23
B24: 20 | C24: =DATE(YEAR(Inputs!C11),MONTH(Inputs!C11)+(20-1)*(12/Inputs!C8),DAY(Inputs!C11)) | D24: =IF(20<=Inputs!C10*Inputs!C8,Inputs!C6*Inputs!C7/Inputs!C8,0) | E24: =IF(Inputs!C12="Bullet",IF(20=Inputs!C10*Inputs!C8,IF(Inputs!C12="Bullet",Inputs!C6,0),0),IF(Inputs!C12="Full",IF(20<=Inputs!C10*Inputs!C8,Inputs!C6/(Inputs!C10*Inputs!C8),0),IF(20<=Inputs!C10*Inputs!C8,MAX(Inputs!C6*Inputs!C13/Inputs!C8-SUM($D$5:$D23),0),0))) | F24: =D24+E24 | G24: =IFERROR(1/(1+Inputs!C9/Inputs!C8)^20,"") | H24: =F24*G24
B25: 21 | C25: =DATE(YEAR(Inputs!C11),MONTH(Inputs!C11)+(21-1)*(12/Inputs!C8),DAY(Inputs!C11)) | D25: =IF(21<=Inputs!C10*Inputs!C8,Inputs!C6*Inputs!C7/Inputs!C8,0) | E25: =IF(Inputs!C12="Bullet",IF(21=Inputs!C10*Inputs!C8,IF(Inputs!C12="Bullet",Inputs!C6,0),0),IF(Inputs!C12="Full",IF(21<=Inputs!C10*Inputs!C8,Inputs!C6/(Inputs!C10*Inputs!C8),0),IF(21<=Inputs!C10*Inputs!C8,MAX(Inputs!C6*Inputs!C13/Inputs!C8-SUM($D$5:$D24),0),0))) | F25: =D25+E25 | G25: =IFERROR(1/(1+Inputs!C9/Inputs!C8)^21,"") | H25: =F25*G25
B26: 22 | C26: =DATE(YEAR(Inputs!C11),MONTH(Inputs!C11)+(22-1)*(12/Inputs!C8),DAY(Inputs!C11)) | D26: =IF(22<=Inputs!C10*Inputs!C8,Inputs!C6*Inputs!C7/Inputs!C8,0) | E26: =IF(Inputs!C12="Bullet",IF(22=Inputs!C10*Inputs!C8,IF(Inputs!C12="Bullet",Inputs!C6,0),0),IF(Inputs!C12="Full",IF(22<=Inputs!C10*Inputs!C8,Inputs!C6/(Inputs!C10*Inputs!C8),0),IF(22<=Inputs!C10*Inputs!C8,MAX(Inputs!C6*Inputs!C13/Inputs!C8-SUM($D$5:$D25),0),0))) | F26: =D26+E26 | G26: =IFERROR(1/(1+Inputs!C9/Inputs!C8)^22,"") | H26: =F26*G26
B27: 23 | C27: =DATE(YEAR(Inputs!C11),MONTH(Inputs!C11)+(23-1)*(12/Inputs!C8),DAY(Inputs!C11)) | D27: =IF(23<=Inputs!C10*Inputs!C8,Inputs!C6*Inputs!C7/Inputs!C8,0) | E27: =IF(Inputs!C12="Bullet",IF(23=Inputs!C10*Inputs!C8,IF(Inputs!C12="Bullet",Inputs!C6,0),0),IF(Inputs!C12="Full",IF(23<=Inputs!C10*Inputs!C8,Inputs!C6/(Inputs!C10*Inputs!C8),0),IF(23<=Inputs!C10*Inputs!C8,MAX(Inputs!C6*Inputs!C13/Inputs!C8-SUM($D$5:$D26),0),0))) | F27: =D27+E27 | G27: =IFERROR(1/(1+Inputs!C9/Inputs!C8)^23,"") | H27: =F27*G27
B28: 24 | C28: =DATE(YEAR(Inputs!C11),MONTH(Inputs!C11)+(24-1)*(12/Inputs!C8),DAY(Inputs!C11)) | D28: =IF(24<=Inputs!C10*Inputs!C8,Inputs!C6*Inputs!C7/Inputs!C8,0) | E28: =IF(Inputs!C12="Bullet",IF(24=Inputs!C10*Inputs!C8,IF(Inputs!C12="Bullet",Inputs!C6,0),0),IF(Inputs!C12="Full",IF(24<=Inputs!C10*Inputs!C8,Inputs!C6/(Inputs!C10*Inputs!C8),0),IF(24<=Inputs!C10*Inputs!C8,MAX(Inputs!C6*Inputs!C13/Inputs!C8-SUM($D$5:$D27),0),0))) | F28: =D28+E28 | G28: =IFERROR(1/(1+Inputs!C9/Inputs!C8)^24,"") | H28: =F28*G28
B29: 25 | C29: =DATE(YEAR(Inputs!C11),MONTH(Inputs!C11)+(25-1)*(12/Inputs!C8),DAY(Inputs!C11)) | D29: =IF(25<=Inputs!C10*Inputs!C8,Inputs!C6*Inputs!C7/Inputs!C8,0) | E29: =IF(Inputs!C12="Bullet",IF(25=Inputs!C10*Inputs!C8,IF(Inputs!C12="Bullet",Inputs!C6,0),0),IF(Inputs!C12="Full",IF(25<=Inputs!C10*Inputs!C8,Inputs!C6/(Inputs!C10*Inputs!C8),0),IF(25<=Inputs!C10*Inputs!C8,MAX(Inputs!C6*Inputs!C13/Inputs!C8-SUM($D$5:$D28),0),0))) | F29: =D29+E29 | G29: =IFERROR(1/(1+Inputs!C9/Inputs!C8)^25,"") | H29: =F29*G29
B30: 26 | C30: =DATE(YEAR(Inputs!C11),MONTH(Inputs!C11)+(26-1)*(12/Inputs!C8),DAY(Inputs!C11)) | D30: =IF(26<=Inputs!C10*Inputs!C8,Inputs!C6*Inputs!C7/Inputs!C8,0) | E30: =IF(Inputs!C12="Bullet",IF(26=Inputs!C10*Inputs!C8,IF(Inputs!C12="Bullet",Inputs!C6,0),0),IF(Inputs!C12="Full",IF(26<=Inputs!C10*Inputs!C8,Inputs!C6/(Inputs!C10*Inputs!C8),0),IF(26<=Inputs!C10*Inputs!C8,MAX(Inputs!C6*Inputs!C13/Inputs!C8-SUM($D$5:$D29),0),0))) | F30: =D30+E30 | G30: =IFERROR(1/(1+Inputs!C9/Inputs!C8)^26,"") | H30: =F30*G30
B31: 27 | C31: =DATE(YEAR(Inputs!C11),MONTH(Inputs!C11)+(27-1)*(12/Inputs!C8),DAY(Inputs!C11)) | D31: =IF(27<=Inputs!C10*Inputs!C8,Inputs!C6*Inputs!C7/Inputs!C8,0) | E31: =IF(Inputs!C12="Bullet",IF(27=Inputs!C10*Inputs!C8,IF(Inputs!C12="Bullet",Inputs!C6,0),0),IF(Inputs!C12="Full",IF(27<=Inputs!C10*Inputs!C8,Inputs!C6/(Inputs!C10*Inputs!C8),0),IF(27<=Inputs!C10*Inputs!C8,MAX(Inputs!C6*Inputs!C13/Inputs!C8-SUM($D$5:$D30),0),0))) | F31: =D31+E31 | G31: =IFERROR(1/(1+Inputs!C9/Inputs!C8)^27,"") | H31: =F31*G31
B32: 28 | C32: =DATE(YEAR(Inputs!C11),MONTH(Inputs!C11)+(28-1)*(12/Inputs!C8),DAY(Inputs!C11)) | D32: =IF(28<=Inputs!C10*Inputs!C8,Inputs!C6*Inputs!C7/Inputs!C8,0) | E32: =IF(Inputs!C12="Bullet",IF(28=Inputs!C10*Inputs!C8,IF(Inputs!C12="Bullet",Inputs!C6,0),0),IF(Inputs!C12="Full",IF(28<=Inputs!C10*Inputs!C8,Inputs!C6/(Inputs!C10*Inputs!C8),0),IF(28<=Inputs!C10*Inputs!C8,MAX(Inputs!C6*Inputs!C13/Inputs!C8-SUM($D$5:$D31),0),0))) | F32: =D32+E32 | G32: =IFERROR(1/(1+Inputs!C9/Inputs!C8)^28,"") | H32: =F32*G32
B33: 29 | C33: =DATE(YEAR(Inputs!C11),MONTH(Inputs!C11)+(29-1)*(12/Inputs!C8),DAY(Inputs!C11)) | D33: =IF(29<=Inputs!C10*Inputs!C8,Inputs!C6*Inputs!C7/Inputs!C8,0) | E33: =IF(Inputs!C12="Bullet",IF(29=Inputs!C10*Inputs!C8,IF(Inputs!C12="Bullet",Inputs!C6,0),0),IF(Inputs!C12="Full",IF(29<=Inputs!C10*Inputs!C8,Inputs!C6/(Inputs!C10*Inputs!C8),0),IF(29<=Inputs!C10*Inputs!C8,MAX(Inputs!C6*Inputs!C13/Inputs!C8-SUM($D$5:$D32),0),0))) | F33: =D33+E33 | G33: =IFERROR(1/(1+Inputs!C9/Inputs!C8)^29,"") | H33: =F33*G33
B34: 30 | C34: =DATE(YEAR(Inputs!C11),MONTH(Inputs!C11)+(30-1)*(12/Inputs!C8),DAY(Inputs!C11)) | D34: =IF(30<=Inputs!C10*Inputs!C8,Inputs!C6*Inputs!C7/Inputs!C8,0) | E34: =IF(Inputs!C12="Bullet",IF(30=Inputs!C10*Inputs!C8,IF(Inputs!C12="Bullet",Inputs!C6,0),0),IF(Inputs!C12="Full",IF(30<=Inputs!C10*Inputs!C8,Inputs!C6/(Inputs!C10*Inputs!C8),0),IF(30<=Inputs!C10*Inputs!C8,MAX(Inputs!C6*Inputs!C13/Inputs!C8-SUM($D$5:$D33),0),0))) | F34: =D34+E34 | G34: =IFERROR(1/(1+Inputs!C9/Inputs!C8)^30,"") | H34: =F34*G34
B35: 31 | C35: =DATE(YEAR(Inputs!C11),MONTH(Inputs!C11)+(31-1)*(12/Inputs!C8),DAY(Inputs!C11)) | D35: =IF(31<=Inputs!C10*Inputs!C8,Inputs!C6*Inputs!C7/Inputs!C8,0) | E35: =IF(Inputs!C12="Bullet",IF(31=Inputs!C10*Inputs!C8,IF(Inputs!C12="Bullet",Inputs!C6,0),0),IF(Inputs!C12="Full",IF(31<=Inputs!C10*Inputs!C8,Inputs!C6/(Inputs!C10*Inputs!C8),0),IF(31<=Inputs!C10*Inputs!C8,MAX(Inputs!C6*Inputs!C13/Inputs!C8-SUM($D$5:$D34),0),0))) | F35: =D35+E35 | G35: =IFERROR(1/(1+Inputs!C9/Inputs!C8)^31,"") | H35: =F35*G35
B36: 32 | C36: =DATE(YEAR(Inputs!C11),MONTH(Inputs!C11)+(32-1)*(12/Inputs!C8),DAY(Inputs!C11)) | D36: =IF(32<=Inputs!C10*Inputs!C8,Inputs!C6*Inputs!C7/Inputs!C8,0) | E36: =IF(Inputs!C12="Bullet",IF(32=Inputs!C10*Inputs!C8,IF(Inputs!C12="Bullet",Inputs!C6,0),0),IF(Inputs!C12="Full",IF(32<=Inputs!C10*Inputs!C8,Inputs!C6/(Inputs!C10*Inputs!C8),0),IF(32<=Inputs!C10*Inputs!C8,MAX(Inputs!C6*Inputs!C13/Inputs!C8-SUM($D$5:$D35),0),0))) | F36: =D36+E36 | G36: =IFERROR(1/(1+Inputs!C9/Inputs!C8)^32,"") | H36: =F36*G36
B37: 33 | C37: =DATE(YEAR(Inputs!C11),MONTH(Inputs!C11)+(33-1)*(12/Inputs!C8),DAY(Inputs!C11)) | D37: =IF(33<=Inputs!C10*Inputs!C8,Inputs!C6*Inputs!C7/Inputs!C8,0) | E37: =IF(Inputs!C12="Bullet",IF(33=Inputs!C10*Inputs!C8,IF(Inputs!C12="Bullet",Inputs!C6,0),0),IF(Inputs!C12="Full",IF(33<=Inputs!C10*Inputs!C8,Inputs!C6/(Inputs!C10*Inputs!C8),0),IF(33<=Inputs!C10*Inputs!C8,MAX(Inputs!C6*Inputs!C13/Inputs!C8-SUM($D$5:$D36),0),0))) | F37: =D37+E37 | G37: =IFERROR(1/(1+Inputs!C9/Inputs!C8)^33,"") | H37: =F37*G37
B38: 34 | C38: =DATE(YEAR(Inputs!C11),MONTH(Inputs!C11)+(34-1)*(12/Inputs!C8),DAY(Inputs!C11)) | D38: =IF(34<=Inputs!C10*Inputs!C8,Inputs!C6*Inputs!C7/Inputs!C8,0) | E38: =IF(Inputs!C12="Bullet",IF(34=Inputs!C10*Inputs!C8,IF(Inputs!C12="Bullet",Inputs!C6,0),0),IF(Inputs!C12="Full",IF(34<=Inputs!C10*Inputs!C8,Inputs!C6/(Inputs!C10*Inputs!C8),0),IF(34<=Inputs!C10*Inputs!C8,MAX(Inputs!C6*Inputs!C13/Inputs!C8-SUM($D$5:$D37),0),0))) | F38: =D38+E38 | G38: =IFERROR(1/(1+Inputs!C9/Inputs!C8)^34,"") | H38: =F38*G38
B39: 35 | C39: =DATE(YEAR(Inputs!C11),MONTH(Inputs!C11)+(35-1)*(12/Inputs!C8),DAY(Inputs!C11)) | D39: =IF(35<=Inputs!C10*Inputs!C8,Inputs!C6*Inputs!C7/Inputs!C8,0) | E39: =IF(Inputs!C12="Bullet",IF(35=Inputs!C10*Inputs!C8,IF(Inputs!C12="Bullet",Inputs!C6,0),0),IF(Inputs!C12="Full",IF(35<=Inputs!C10*Inputs!C8,Inputs!C6/(Inputs!C10*Inputs!C8),0),IF(35<=Inputs!C10*Inputs!C8,MAX(Inputs!C6*Inputs!C13/Inputs!C8-SUM($D$5:$D38),0),0))) | F39: =D39+E39 | G39: =IFERROR(1/(1+Inputs!C9/Inputs!C8)^35,"") | H39: =F39*G39
B40: 36 | C40: =DATE(YEAR(Inputs!C11),MONTH(Inputs!C11)+(36-1)*(12/Inputs!C8),DAY(Inputs!C11)) | D40: =IF(36<=Inputs!C10*Inputs!C8,Inputs!C6*Inputs!C7/Inputs!C8,0) | E40: =IF(Inputs!C12="Bullet",IF(36=Inputs!C10*Inputs!C8,IF(Inputs!C12="Bullet",Inputs!C6,0),0),IF(Inputs!C12="Full",IF(36<=Inputs!C10*Inputs!C8,Inputs!C6/(Inputs!C10*Inputs!C8),0),IF(36<=Inputs!C10*Inputs!C8,MAX(Inputs!C6*Inputs!C13/Inputs!C8-SUM($D$5:$D39),0),0))) | F40: =D40+E40 | G40: =IFERROR(1/(1+Inputs!C9/Inputs!C8)^36,"") | H40: =F40*G40
...

Sheet Results
B1: DURATION & RISK METRICS — LIVE OUTPUTS
B2: All values update automatically when Inputs are changed
B4: METRIC | C4: VALUE | D4: FORMULA / NOTES
B6: Number of Periods | C6: =Inputs!C10*Inputs!C8 | D6: Tenor × Frequency
B7: Periodic Coupon Amount (₹ Cr) | C7: =Inputs!C6*Inputs!C7/Inputs!C8 | D7: Principal × Coupon Rate / Frequency
B8: ➤ Macaulay Duration (Years) | C8: ='Cash Flows'!I126 | D8: Weighted avg time to receive cash flows
B9: Modified Duration (Years) | C9: =C8/(1+Inputs!C9/Inputs!C8) | D9: Macaulay / (1 + y/f) — price sensitivity to yield
B10: DV01 — ₹ Cr per basis point | C10: =(C9*Inputs!C6)/10000 | D10: Price change per 1bp yield increase
B11: Convexity | C11: =((1+Inputs!C9/Inputs!C8)^2*C9/(Inputs!C9/Inputs!C8)^2)-((1+Inputs!C9/Inputs!C8)*Inputs!C9/Inputs!C8+1)/((Inputs!C9/Inputs!C8)^2*(1+Inputs!C9/Inputs!C8)) | D11: Second-order price sensitivity — for small yield changes
B12: Price per ₹100 Face (₹) | C12: =SUMPRODUCT((1/(1+Inputs!C9/Inputs!C8)^ROW(INDIRECT("1:"&Inputs!C8*Inputs!C10)))*(IF(ROW(INDIRECT("1:"&Inputs!C8*Inputs!C10))<Inputs!C8*Inputs!C10,Inputs!C6*Inputs!C7/Inputs!C8,Inputs!C6*Inputs!C7/Inputs!C8+Inputs!C6)))/(Inputs!C6*100)) | D12: Issue price / market price per ₹100 face value
B13: Modified Duration × Face Value (₹ Cr) | C13: =C9*Inputs!C6 | D13: Duration × Notional — for hedging
B14: Price Change per +100bp (₹ Cr) | C14: =-C9*Inputs!C6*0.01+C12*0.5*C11*0.0001 | D14: Approx price drop for 100bp yield rise (includes convexity)
B15: Price Change per -100bp (₹ Cr) | C15: =C9*Inputs!C6*0.01+C12*0.5*C11*0.0001 | D15: Approx price rise for 100bp yield fall (includes convexity)
B16: Annualised Cost (if borrowing — all-in %) | C16: =Inputs!C7+((100-C12)/C8) | D16: Approx all-in cost if issued at discount/premium
B18: KEY ASSUMPTIONS
B20: ✓ Flat yield curve — same yield used for all periods
B21: ✓ Coupon dates equally spaced at 1/f years
B22: ✓ No call/put options embedded (plain vanilla loan)
B23: ✓ Day count: 30/360 (change in CF sheet if ACT/ACT needed)
B24: ✓ Convexity formula: simplified approximation (Taylor series)
B26: 🔑 Green = Key duration metrics | Yellow = Derived / price metrics | Red = Downside sensitivity

Sheet What-If
B1: YIELD vs DURATION — SENSITIVITY TABLE
B2: Rows = Yield scenarios (YTM) | Columns = Tenor scenarios (Years) | Values = Modified Duration in Years
B4: Yield \ Tenor → | C4: 1Y | D4: 2Y | E4: 3Y | F4: 4Y | G4: 5Y | H4: 6Y | I4: 7Y | J4: 8Y | K4: 9Y | L4: 10Y | M4: 11Y | N4: 12Y | O4: 13Y | P4: 14Y | Q4: 15Y
B5: 5.00% | C5: =IFERROR(1/(1+5.0/100),0) | D5: =IFERROR(2/(1+5.0/100),0) | E5: =IFERROR(3/(1+5.0/100),0) | F5: =IFERROR(4/(1+5.0/100),0) | G5: =IFERROR(5/(1+5.0/100),0) | H5: =IFERROR(6/(1+5.0/100),0) | I5: =IFERROR(7/(1+5.0/100),0) | J5: =IFERROR(8/(1+5.0/100),0) | K5: =IFERROR(9/(1+5.0/100),0) | L5: =IFERROR(10/(1+5.0/100),0) | M5: =IFERROR(11/(1+5.0/100),0) | N5: =IFERROR(12/(1+5.0/100),0) | O5: =IFERROR(13/(1+5.0/100),0) | P5: =IFERROR(14/(1+5.0/100),0) | Q5: =IFERROR(15/(1+5.0/100),0)
B6: 5.25% | C6: =IFERROR(1/(1+5.25/100),0) | D6: =IFERROR(2/(1+5.25/100),0) | E6: =IFERROR(3/(1+5.25/100),0) | F6: =IFERROR(4/(1+5.25/100),0) | G6: =IFERROR(5/(1+5.25/100),0) | H6: =IFERROR(6/(1+5.25/100),0) | I6: =IFERROR(7/(1+5.25/100),0) | J6: =IFERROR(8/(1+5.25/100),0) | K6: =IFERROR(9/(1+5.25/100),0) | L6: =IFERROR(10/(1+5.25/100),0) | M6: =IFERROR(11/(1+5.25/100),0) | N6: =IFERROR(12/(1+5.25/100),0) | O6: =IFERROR(13/(1+5.25/100),0) | P6: =IFERROR(14/(1+5.25/100),0) | Q6: =IFERROR(15/(1+5.25/100),0)
B7: 5.50% | C7: =IFERROR(1/(1+5.5/100),0) | D7: =IFERROR(2/(1+5.5/100),0) | E7: =IFERROR(3/(1+5.5/100),0) | F7: =IFERROR(4/(1+5.5/100),0) | G7: =IFERROR(5/(1+5.5/100),0) | H7: =IFERROR(6/(1+5.5/100),0) | I7: =IFERROR(7/(1+5.5/100),0) | J7: =IFERROR(8/(1+5.5/100),0) | K7: =IFERROR(9/(1+5.5/100),0) | L7: =IFERROR(10/(1+5.5/100),0) | M7: =IFERROR(11/(1+5.5/100),0) | N7: =IFERROR(12/(1+5.5/100),0) | O7: =IFERROR(13/(1+5.5/100),0) | P7: =IFERROR(14/(1+5.5/100),0) | Q7: =IFERROR(15/(1+5.5/100),0)
B8: 5.75% | C8: =IFERROR(1/(1+5.75/100),0) | D8: =IFERROR(2/(1+5.75/100),0) | E8: =IFERROR(3/(1+5.75/100),0) | F8: =IFERROR(4/(1+5.75/100),0) | G8: =IFERROR(5/(1+5.75/100),0) | H8: =IFERROR(6/(1+5.75/100),0) | I8: =IFERROR(7/(1+5.75/100),0) | J8: =IFERROR(8/(1+5.75/100),0) | K8: =IFERROR(9/(1+5.75/100),0) | L8: =IFERROR(10/(1+5.75/100),0) | M8: =IFERROR(11/(1+5.75/100),0) | N8: =IFERROR(12/(1+5.75/100),0) | O8: =IFERROR(13/(1+5.75/100),0) | P8: =IFERROR(14/(1+5.75/100),0) | Q8: =IFERROR(15/(1+5.75/100),0)
B9: 6.00% | C9: =IFERROR(1/(1+6.0/100),0) | D9: =IFERROR(2/(1+6.0/100),0) | E9: =IFERROR(3/(1+6.0/100),0) | F9: =IFERROR(4/(1+6.0/100),0) | G9: =IFERROR(5/(1+6.0/100),0) | H9: =IFERROR(6/(1+6.0/100),0) | I9: =IFERROR(7/(1+6.0/100),0) | J9: =IFERROR(8/(1+6.0/100),0) | K9: =IFERROR(9/(1+6.0/100),0) | L9: =IFERROR(10/(1+6.0/100),0) | M9: =IFERROR(11/(1+6.0/100),0) | N9: =IFERROR(12/(1+6.0/100),0) | O9: =IFERROR(13/(1+6.0/100),0) | P9: =IFERROR(14/(1+6.0/100),0) | Q9: =IFERROR(15/(1+6.0/100),0)
B10: 6.25% | C10: =IFERROR(1/(1+6.25/100),0) | D10: =IFERROR(2/(1+6.25/100),0) | E10: =IFERROR(3/(1+6.25/100),0) | F10: =IFERROR(4/(1+6.25/100),0) | G10: =IFERROR(5/(1+6.25/100),0) | H10: =IFERROR(6/(1+6.25/100),0) | I10: =IFERROR(7/(1+6.25/100),0) | J10: =IFERROR(8/(1+6.25/100),0) | K10: =IFERROR(9/(1+6.25/100),0) | L10: =IFERROR(10/(1+6.25/100),0) | M10: =IFERROR(11/(1+6.25/100),0) | N10: =IFERROR(12/(1+6.25/100),0) | O10: =IFERROR(13/(1+6.25/100),0) | P10: =IFERROR(14/(1+6.25/100),0) | Q10: =IFERROR(15/(1+6.25/100),0)
B11: 6.50% | C11: =IFERROR(1/(1+6.5/100),0) | D11: =IFERROR(2/(1+6.5/100),0) | E11: =IFERROR(3/(1+6.5/100),0) | F11: =IFERROR(4/(1+6.5/100),0) | G11: =IFERROR(5/(1+6.5/100),0) | H11: =IFERROR(6/(1+6.5/100),0) | I11: =IFERROR(7/(1+6.5/100),0) | J11: =IFERROR(8/(1+6.5/100),0) | K11: =IFERROR(9/(1+6.5/100),0) | L11: =IFERROR(10/(1+6.5/100),0) | M11: =IFERROR(11/(1+6.5/100),0) | N11: =IFERROR(12/(1+6.5/100),0) | O11: =IFERROR(13/(1+6.5/100),0) | P11: =IFERROR(14/(1+6.5/100),0) | Q11: =IFERROR(15/(1+6.5/100),0)
B12: 6.75% | C12: =IFERROR(1/(1+6.75/100),0) | D12: =IFERROR(2/(1+6.75/100),0) | E12: =IFERROR(3/(1+6.75/100),0) | F12: =IFERROR(4/(1+6.75/100),0) | G12: =IFERROR(5/(1+6.75/100),0) | H12: =IFERROR(6/(1+6.75/100),0) | I12: =IFERROR(7/(1+6.75/100),0) | J12: =IFERROR(8/(1+6.75/100),0) | K12: =IFERROR(9/(1+6.75/100),0) | L12: =IFERROR(10/(1+6.75/100),0) | M12: =IFERROR(11/(1+6.75/100),0) | N12: =IFERROR(12/(1+6.75/100),0) | O12: =IFERROR(13/(1+6.75/100),0) | P12: =IFERROR(14/(1+6.75/100),0) | Q12: =IFERROR(15/(1+6.75/100),0)
B13: 7.00% | C13: =IFERROR(1/(1+7.0/100),0) | D13: =IFERROR(2/(1+7.0/100),0) | E13: =IFERROR(3/(1+7.0/100),0) | F13: =IFERROR(4/(1+7.0/100),0) | G13: =IFERROR(5/(1+7.0/100),0) | H13: =IFERROR(6/(1+7.0/100),0) | I13: =IFERROR(7/(1+7.0/100),0) | J13: =IFERROR(8/(1+7.0/100),0) | K13: =IFERROR(9/(1+7.0/100),0) | L13: =IFERROR(10/(1+7.0/100),0) | M13: =IFERROR(11/(1+7.0/100),0) | N13: =IFERROR(12/(1+7.0/100),0) | O13: =IFERROR(13/(1+7.0/100),0) | P13: =IFERROR(14/(1+7.0/100),0) | Q13: =IFERROR(15/(1+7.0/100),0)
B14: 7.25% | C14: =IFERROR(1/(1+7.25/100),0) | D14: =IFERROR(2/(1+7.25/100),0) | E14: =IFERROR(3/(1+7.25/100),0) | F14: =IFERROR(4/(1+7.25/100),0) | G14: =IFERROR(5/(1+7.25/100),0) | H14: =IFERROR(6/(1+7.25/100),0) | I14: =IFERROR(7/(1+7.25/100),0) | J14: =IFERROR(8/(1+7.25/100),0) | K14: =IFERROR(9/(1+7.25/100),0) | L14: =IFERROR(10/(1+7.25/100),0) | M14: =IFERROR(11/(1+7.25/100),0) | N14: =IFERROR(12/(1+7.25/100),0) | O14: =IFERROR(13/(1+7.25/100),0) | P14: =IFERROR(14/(1+7.25/100),0) | Q14: =IFERROR(15/(1+7.25/100),0)
B15: 7.50% | C15: =IFERROR(1/(1+7.5/100),0) | D15: =IFERROR(2/(1+7.5/100),0) | E15: =IFERROR(3/(1+7.5/100),0) | F15: =IFERROR(4/(1+7.5/100),0) | G15: =IFERROR(5/(1+7.5/100),0) | H15: =IFERROR(6/(1+7.5/100),0) | I15: =IFERROR(7/(1+7.5/100),0) | J15: =IFERROR(8/(1+7.5/100),0) | K15: =IFERROR(9/(1+7.5/100),0) | L15: =IFERROR(10/(1+7.5/100),0) | M15: =IFERROR(11/(1+7.5/100),0) | N15: =IFERROR(12/(1+7.5/100),0) | O15: =IFERROR(13/(1+7.5/100),0) | P15: =IFERROR(14/(1+7.5/100),0) | Q15: =IFERROR(15/(1+7.5/100),0)
B16: 7.75% | C16: =IFERROR(1/(1+7.75/100),0) | D16: =IFERROR(2/(1+7.75/100),0) | E16: =IFERROR(3/(1+7.75/100),0) | F16: =IFERROR(4/(1+7.75/100),0) | G16: =IFERROR(5/(1+7.75/100),0) | H16: =IFERROR(6/(1+7.75/100),0) | I16: =IFERROR(7/(1+7.75/100),0) | J16: =IFERROR(8/(1+7.75/100),0) | K16: =IFERROR(9/(1+7.75/100),0) | L16: =IFERROR(10/(1+7.75/100),0) | M16: =IFERROR(11/(1+7.75/100),0) | N16: =IFERROR(12/(1+7.75/100),0) | O16: =IFERROR(13/(1+7.75/100),0) | P16: =IFERROR(14/(1+7.75/100),0) | Q16: =IFERROR(15/(1+7.75/100),0)
B17: 8.00% | C17: =IFERROR(1/(1+8.0/100),0) | D17: =IFERROR(2/(1+8.0/100),0) | E17: =IFERROR(3/(1+8.0/100),0) | F17: =IFERROR(4/(1+8.0/100),0) | G17: =IFERROR(5/(1+8.0/100),0) | H17: =IFERROR(6/(1+8.0/100),0) | I17: =IFERROR(7/(1+8.0/100),0) | J17: =IFERROR(8/(1+8.0/100),0) | K17: =IFERROR(9/(1+8.0/100),0) | L17: =IFERROR(10/(1+8.0/100),0) | M17: =IFERROR(11/(1+8.0/100),0) | N17: =IFERROR(12/(1+8.0/100),0) | O17: =IFERROR(13/(1+8.0/100),0) | P17: =IFERROR(14/(1+8.0/100),0) | Q17: =IFERROR(15/(1+8.0/100),0)
B18: 8.25% | C18: =IFERROR(1/(1+8.25/100),0) | D18: =IFERROR(2/(1+8.25/100),0) | E18: =IFERROR(3/(1+8.25/100),0) | F18: =IFERROR(4/(1+8.25/100),0) | G18: =IFERROR(5/(1+8.25/100),0) | H18: =IFERROR(6/(1+8.25/100),0) | I18: =IFERROR(7/(1+8.25/100),0) | J18: =IFERROR(8/(1+8.25/100),0) | K18: =IFERROR(9/(1+8.25/100),0) | L18: =IFERROR(10/(1+8.25/100),0) | M18: =IFERROR(11/(1+8.25/100),0) | N18: =IFERROR(12/(1+8.25/100),0) | O18: =IFERROR(13/(1+8.25/100),0) | P18: =IFERROR(14/(1+8.25/100),0) | Q18: =IFERROR(15/(1+8.25/100),0)
B19: 8.50% | C19: =IFERROR(1/(1+8.5/100),0) | D19: =IFERROR(2/(1+8.5/100),0) | E19: =IFERROR(3/(1+8.5/100),0) | F19: =IFERROR(4/(1+8.5/100),0) | G19: =IFERROR(5/(1+8.5/100),0) | H19: =IFERROR(6/(1+8.5/100),0) | I19: =IFERROR(7/(1+8.5/100),0) | J19: =IFERROR(8/(1+8.5/100),0) | K19: =IFERROR(9/(1+8.5/100),0) | L19: =IFERROR(10/(1+8.5/100),0) | M19: =IFERROR(11/(1+8.5/100),0) | N19: =IFERROR(12/(1+8.5/100),0) | O19: =IFERROR(13/(1+8.5/100),0) | P19: =IFERROR(14/(1+8.5/100),0) | Q19: =IFERROR(15/(1+8.5/100),0)
B20: 8.75% | C20: =IFERROR(1/(1+8.75/100),0) | D20: =IFERROR(2/(1+8.75/100),0) | E20: =IFERROR(3/(1+8.75/100),0) | F20: =IFERROR(4/(1+8.75/100),0) | G20: =IFERROR(5/(1+8.75/100),0) | H20: =IFERROR(6/(1+8.75/100),0) | I20: =IFERROR(7/(1+8.75/100),0) | J20: =IFERROR(8/(1+8.75/100),0) | K20: =IFERROR(9/(1+8.75/100),0) | L20: =IFERROR(10/(1+8.75/100),0) | M20: =IFERROR(11/(1+8.75/100),0) | N20: =IFERROR(12/(1+8.75/100),0) | O20: =IFERROR(13/(1+8.75/100),0) | P20: =IFERROR(14/(1+8.75/100),0) | Q20: =IFERROR(15/(1+8.75/100),0)
B21: 9.00% | C21: =IFERROR(1/(1+9.0/100),0) | D21: =IFERROR(2/(1+9.0/100),0) | E21: =IFERROR(3/(1+9.0/100),0) | F21: =IFERROR(4/(1+9.0/100),0) | G21: =IFERROR(5/(1+9.0/100),0) | H21: =IFERROR(6/(1+9.0/100),0) | I21: =IFERROR(7/(1+9.0/100),0) | J21: =IFERROR(8/(1+9.0/100),0) | K21: =IFERROR(9/(1+9.0/100),0) | L21: =IFERROR(10/(1+9.0/100),0) | M21: =IFERROR(11/(1+9.0/100),0) | N21: =IFERROR(12/(1+9.0/100),0) | O21: =IFERROR(13/(1+9.0/100),0) | P21: =IFERROR(14/(1+9.0/100),0) | Q21: =IFERROR(15/(1+9.0/100),0)
B22: 9.25% | C22: =IFERROR(1/(1+9.25/100),0) | D22: =IFERROR(2/(1+9.25/100),0) | E22: =IFERROR(3/(1+9.25/100),0) | F22: =IFERROR(4/(1+9.25/100),0) | G22: =IFERROR(5/(1+9.25/100),0) | H22: =IFERROR(6/(1+9.25/100),0) | I22: =IFERROR(7/(1+9.25/100),0) | J22: =IFERROR(8/(1+9.25/100),0) | K22: =IFERROR(9/(1+9.25/100),0) | L22: =IFERROR(10/(1+9.25/100),0) | M22: =IFERROR(11/(1+9.25/100),0) | N22: =IFERROR(12/(1+9.25/100),0) | O22: =IFERROR(13/(1+9.25/100),0) | P22: =IFERROR(14/(1+9.25/100),0) | Q22: =IFERROR(15/(1+9.25/100),0)
B23: 9.50% | C23: =IFERROR(1/(1+9.5/100),0) | D23: =IFERROR(2/(1+9.5/100),0) | E23: =IFERROR(3/(1+9.5/100),0) | F23: =IFERROR(4/(1+9.5/100),0) | G23: =IFERROR(5/(1+9.5/100),0) | H23: =IFERROR(6/(1+9.5/100),0) | I23: =IFERROR(7/(1+9.5/100),0) | J23: =IFERROR(8/(1+9.5/100),0) | K23: =IFERROR(9/(1+9.5/100),0) | L23: =IFERROR(10/(1+9.5/100),0) | M23: =IFERROR(11/(1+9.5/100),0) | N23: =IFERROR(12/(1+9.5/100),0) | O23: =IFERROR(13/(1+9.5/100),0) | P23: =IFERROR(14/(1+9.5/100),0) | Q23: =IFERROR(15/(1+9.5/100),0)
B24: 9.75% | C24: =IFERROR(1/(1+9.75/100),0) | D24: =IFERROR(2/(1+9.75/100),0) | E24: =IFERROR(3/(1+9.75/100),0) | F24: =IFERROR(4/(1+9.75/100),0) | G24: =IFERROR(5/(1+9.75/100),0) | H24: =IFERROR(6/(1+9.75/100),0) | I24: =IFERROR(7/(1+9.75/100),0) | J24: =IFERROR(8/(1+9.75/100),0) | K24: =IFERROR(9/(1+9.75/100),0) | L24: =IFERROR(10/(1+9.75/100),0) | M24: =IFERROR(11/(1+9.75/100),0) | N24: =IFERROR(12/(1+9.75/100),0) | O24: =IFERROR(13/(1+9.75/100),0) | P24: =IFERROR(14/(1+9.75/100),0) | Q24: =IFERROR(15/(1+9.75/100),0)
B25: 10.00% | C25: =IFERROR(1/(1+10.0/100),0) | D25: =IFERROR(2/(1+10.0/100),0) | E25: =IFERROR(3/(1+10.0/100),0) | F25: =IFERROR(4/(1+10.0/100),0) | G25: =IFERROR(5/(1+10.0/100),0) | H25: =IFERROR(6/(1+10.0/100),0) | I25: =IFERROR(7/(1+10.0/100),0) | J25: =IFERROR(8/(1+10.0/100),0) | K25: =IFERROR(9/(1+10.0/100),0) | L25: =IFERROR(10/(1+10.0/100),0) | M25: =IFERROR(11/(1+10.0/100),0) | N25: =IFERROR(12/(1+10.0/100),0) | O25: =IFERROR(13/(1+10.0/100),0) | P25: =IFERROR(14/(1+10.0/100),0) | Q25: =IFERROR(15/(1+10.0/100),0)
B26: 10.25% | C26: =IFERROR(1/(1+10.25/100),0) | D26: =IFERROR(2/(1+10.25/100),0) | E26: =IFERROR(3/(1+10.25/100),0) | F26: =IFERROR(4/(1+10.25/100),0) | G26: =IFERROR(5/(1+10.25/100),0) | H26: =IFERROR(6/(1+10.25/100),0) | I26: =IFERROR(7/(1+10.25/100),0) | J26: =IFERROR(8/(1+10.25/100),0) | K26: =IFERROR(9/(1+10.25/100),0) | L26: =IFERROR(10/(1+10.25/100),0) | M26: =IFERROR(11/(1+10.25/100),0) | N26: =IFERROR(12/(1+10.25/100),0) | O26: =IFERROR(13/(1+10.25/100),0) | P26: =IFERROR(14/(1+10.25/100),0) | Q26: =IFERROR(15/(1+10.25/100),0)
B27: 10.50% | C27: =IFERROR(1/(1+10.5/100),0) | D27: =IFERROR(2/(1+10.5/100),0) | E27: =IFERROR(3/(1+10.5/100),0) | F27: =IFERROR(4/(1+10.5/100),0) | G27: =IFERROR(5/(1+10.5/100),0) | H27: =IFERROR(6/(1+10.5/100),0) | I27: =IFERROR(7/(1+10.5/100),0) | J27: =IFERROR(8/(1+10.5/100),0) | K27: =IFERROR(9/(1+10.5/100),0) | L27: =IFERROR(10/(1+10.5/100),0) | M27: =IFERROR(11/(1+10.5/100),0) | N27: =IFERROR(12/(1+10.5/100),0) | O27: =IFERROR(13/(1+10.5/100),0) | P27: =IFERROR(14/(1+10.5/100),0) | Q27: =IFERROR(15/(1+10.5/100),0)
B28: 10.75% | C28: =IFERROR(1/(1+10.75/100),0) | D28: =IFERROR(2/(1+10.75/100),0) | E28: =IFERROR(3/(1+10.75/100),0) | F28: =IFERROR(4/(1+10.75/100),0) | G28: =IFERROR(5/(1+10.75/100),0) | H28: =IFERROR(6/(1+10.75/100),0) | I28: =IFERROR(7/(1+10.75/100),0) | J28: =IFERROR(8/(1+10.75/100),0) | K28: =IFERROR(9/(1+10.75/100),0) | L28: =IFERROR(10/(1+10.75/100),0) | M28: =IFERROR(11/(1+10.75/100),0) | N28: =IFERROR(12/(1+10.75/100),0) | O28: =IFERROR(13/(1+10.75/100),0) | P28: =IFERROR(14/(1+10.75/100),0) | Q28: =IFERROR(15/(1+10.75/100),0)
B29: 11.00% | C29: =IFERROR(1/(1+11.0/100),0) | D29: =IFERROR(2/(1+11.0/100),0) | E29: =IFERROR(3/(1+11.0/100),0) | F29: =IFERROR(4/(1+11.0/100),0) | G29: =IFERROR(5/(1+11.0/100),0) | H29: =IFERROR(6/(1+11.0/100),0) | I29: =IFERROR(7/(1+11.0/100),0) | J29: =IFERROR(8/(1+11.0/100),0) | K29: =IFERROR(9/(1+11.0/100),0) | L29: =IFERROR(10/(1+11.0/100),0) | M29: =IFERROR(11/(1+11.0/100),0) | N29: =IFERROR(12/(1+11.0/100),0) | O29: =IFERROR(13/(1+11.0/100),0) | P29: =IFERROR(14/(1+11.0/100),0) | Q29: =IFERROR(15/(1+11.0/100),0)
B31: 📊 VBA Monte Carlo button (Import Macro button below) runs 10,000 yield path simulations and outputs VaR (95%) and CVaR at 99% confidence. Also plots histogram of price outcomes.
B33: 👇 IMPORT VBA MODULE: Developer → Visual Basic → File → Import File → select Duration_Model.bas from the repo. Then assign 'RunWhatIf' to a button.

Sheet Amort Schedule
B1: AMORTISATION SCHEDULE (FULL AMORT TYPE — REFERENCE)
B3: Period | C3: Opening Balance | D3: EMI / Coupon | E3: Interest Portion | F3: Principal Portion | G3: Closing Balance | H3: Cumulative Int.
B4: 1 | C4: =Inputs!C6 | D4: =IF(1<=Inputs!C10*Inputs!C8,Inputs!C6/(Inputs!C10*Inputs!C8)+Inputs!C6*Inputs!C7/Inputs!C8,0) | E4: =C4*Inputs!C7/Inputs!C8 | F4: =D4-E4 | G4: =C4-F4 | H4: =E4
B5: 2 | C5: =G4 | D5: =IF(2<=Inputs!C10*Inputs!C8,Inputs!C6/(Inputs!C10*Inputs!C8)+Inputs!C6*Inputs!C7/Inputs!C8,0) | E5: =C5*Inputs!C7/Inputs!C8 | F5: =D5-E5 | G5: =C5-F5 | H5: =G4+E5
B6: 3 | C6: =G5 | D6: =IF(3<=Inputs!C10*Inputs!C8,Inputs!C6/(Inputs!C10*Inputs!C8)+Inputs!C6*Inputs!C7/Inputs!C8,0) | E6: =C6*Inputs!C7/Inputs!C8 | F6: =D6-E6 | G6: =C6-F6 | H6: =G5+E6
B7: 4 | C7: =G6 | D7: =IF(4<=Inputs!C10*Inputs!C8,Inputs!C6/(Inputs!C10*Inputs!C8)+Inputs!C6*Inputs!C7/Inputs!C8,0) | E7: =C7*Inputs!C7/Inputs!C8 | F7: =D7-E7 | G7: =C7-F7 | H7: =G6+E7
B8: 5 | C8: =G7 | D8: =IF(5<=Inputs!C10*Inputs!C8,Inputs!C6/(Inputs!C10*Inputs!C8)+Inputs!C6*Inputs!C7/Inputs!C8,0) | E8: =C8*Inputs!C7/Inputs!C8 | F8: =D8-E8 | G8: =C8-F8 | H8: =G7+E8
B9: 6 | C9: =G8 | D9: =IF(6<=Inputs!C10*Inputs!C8,Inputs!C6/(Inputs!C10*Inputs!C8)+Inputs!C6*Inputs!C7/Inputs!C8,0) | E9: =C9*Inputs!C7/Inputs!C8 | F9: =D9-E9 | G9: =C9-F9 | H9: =G8+E9
B10: 7 | C10: =G9 | D10: =IF(7<=Inputs!C10*Inputs!C8,Inputs!C6/(Inputs!C10*Inputs!C8)+Inputs!C6*Inputs!C7/Inputs!C8,0) | E10: =C10*Inputs!C7/Inputs!C8 | F10: =D10-E10 | G10: =C10-F10 | H10: =G9+E10
B11: 8 | C11: =G10 | D11: =IF(8<=Inputs!C10*Inputs!C8,Inputs!C6/(Inputs!C10*Inputs!C8)+Inputs!C6*Inputs!C7/Inputs!C8,0) | E11: =C11*Inputs!C7/Inputs!C8 | F11: =D11-E11 | G11: =C11-F11 | H11: =G10+E11
B12: 9 | C12: =G11 | D12: =IF(9<=Inputs!C10*Inputs!C8,Inputs!C6/(Inputs!C10*Inputs!C8)+Inputs!C6*Inputs!C7/Inputs!C8,0) | E12: =C12*Inputs!C7/Inputs!C8 | F12: =D12-E12 | G12: =C12-F12 | H12: =G11+E12
B13: 10 | C13: =G12 | D13: =IF(10<=Inputs!C10*Inputs!C8,Inputs!C6/(Inputs!C10*Inputs!C8)+Inputs!C6*Inputs!C7/Inputs!C8,0) | E13: =C13*Inputs!C7/Inputs!C8 | F13: =D13-E13 | G13: =C13-F13 | H13: =G12+E13
B14: 11 | C14: =G13 | D14: =IF(11<=Inputs!C10*Inputs!C8,Inputs!C6/(Inputs!C10*Inputs!C8)+Inputs!C6*Inputs!C7/Inputs!C8,0) | E14: =C14*Inputs!C7/Inputs!C8 | F14: =D14-E14 | G14: =C14-F14 | H14: =G13+E14
B15: 12 | C15: =G14 | D15: =IF(12<=Inputs!C10*Inputs!C8,Inputs!C6/(Inputs!C10*Inputs!C8)+Inputs!C6*Inputs!C7/Inputs!C8,0) | E15: =C15*Inputs!C7/Inputs!C8 | F15: =D15-E15 | G15: =C15-F15 | H15: =G14+E15
B16: 13 | C16: =G15 | D16: =IF(13<=Inputs!C10*Inputs!C8,Inputs!C6/(Inputs!C10*Inputs!C8)+Inputs!C6*Inputs!C7/Inputs!C8,0) | E16: =C16*Inputs!C7/Inputs!C8 | F16: =D16-E16 | G16: =C16-F16 | H16: =G15+E16
B17: 14 | C17: =G16 | D17: =IF(14<=Inputs!C10*Inputs!C8,Inputs!C6/(Inputs!C10*Inputs!C8)+Inputs!C6*Inputs!C7/Inputs!C8,0) | E17: =C17*Inputs!C7/Inputs!C8 | F17: =D17-E17 | G17: =C17-F17 | H17: =G16+E17
B18: 15 | C18: =G17 | D18: =IF(15<=Inputs!C10*Inputs!C8,Inputs!C6/(Inputs!C10*Inputs!C8)+Inputs!C6*Inputs!C7/Inputs!C8,0) | E18: =C18*Inputs!C7/Inputs!C8 | F18: =D18-E18 | G18: =C18-F18 | H18: =G17+E18
B19: 16 | C19: =G18 | D19: =IF(16<=Inputs!C10*Inputs!C8,Inputs!C6/(Inputs!C10*Inputs!C8)+Inputs!C6*Inputs!C7/Inputs!C8,0) | E19: =C19*Inputs!C7/Inputs!C8 | F19: =D19-E19 | G19: =C19-F19 | H19: =G18+E19
B20: 17 | C20: =G19 | D20: =IF(17<=Inputs!C10*Inputs!C8,Inputs!C6/(Inputs!C10*Inputs!C8)+Inputs!C6*Inputs!C7/Inputs!C8,0) | E20: =C20*Inputs!C7/Inputs!C8 | F20: =D20-E20 | G20: =C20-F20 | H20: =G19+E20
B21: 18 | C21: =G20 | D21: =IF(18<=Inputs!C10*Inputs!C8,Inputs!C6/(Inputs!C10*Inputs!C8)+Inputs!C6*Inputs!C7/Inputs!C8,0) | E21: =C21*Inputs!C7/Inputs!C8 | F21: =D21-E21 | G21: =C21-F21 | H21: =G20+E21
B22: 19 | C22: =G21 | D22: =IF(19<=Inputs!C10*Inputs!C8,Inputs!C6/(Inputs!C10*Inputs!C8)+Inputs!C6*Inputs!C7/Inputs!C8,0) | E22: =C22*Inputs!C7/Inputs!C8 | F22: =D22-E22 | G22: =C22-F22 | H22: =G21+E22
B23: 20 | C23: =G22 | D23: =IF(20<=Inputs!C10*Inputs!C8,Inputs!C6/(Inputs!C10*Inputs!C8)+Inputs!C6*Inputs!C7/Inputs!C8,0) | E23: =C23*Inputs!C7/Inputs!C8 | F23: =D23-E23 | G23: =C23-F23 | H23: =G22+E23
B24: 21 | C24: =G23 | D24: =IF(21<=Inputs!C10*Inputs!C8,Inputs!C6/(Inputs!C10*Inputs!C8)+Inputs!C6*Inputs!C7/Inputs!C8,0) | E24: =C24*Inputs!C7/Inputs!C8 | F24: =D24-E24 | G24: =C24-F24 | H24: =G23+E24
B25: 22 | C25: =G24 | D25: =IF(22<=Inputs!C10*Inputs!C8,Inputs!C6/(Inputs!C10*Inputs!C8)+Inputs!C6*Inputs!C7/Inputs!C8,0) | E25: =C25*Inputs!C7/Inputs!C8 | F25: =D25-E25 | G25: =C25-F25 | H25: =G24+E25
B26: 23 | C26: =G25 | D26: =IF(23<=Inputs!C10*Inputs!C8,Inputs!C6/(Inputs!C10*Inputs!C8)+Inputs!C6*Inputs!C7/Inputs!C8,0) | E26: =C26*Inputs!C7/Inputs!C8 | F26: =D26-E26 | G26: =C26-F26 | H26: =G25+E26
B27: 24 | C27: =G26 | D27: =IF(24<=Inputs!C10*Inputs!C8,Inputs!C6/(Inputs!C10*Inputs!C8)+Inputs!C6*Inputs!C7/Inputs!C8,0) | E27: =C27*Inputs!C7/Inputs!C8 | F27: =D27-E27 | G27: =C27-F27 | H27: =G26+E27
B28: 25 | C28: =G27 | D28: =IF(25<=Inputs!C10*Inputs!C8,Inputs!C6/(Inputs!C10*Inputs!C8)+Inputs!C6*Inputs!C7/Inputs!C8,0) | E28: =C28*Inputs!C7/Inputs!C8 | F28: =D28-E28 | G28: =C28-F28 | H28: =G27+E28
B29: 26 | C29: =G28 | D29: =IF(26<=Inputs!C10*Inputs!C8,Inputs!C6/(Inputs!C10*Inputs!C8)+Inputs!C6*Inputs!C7/Inputs!C8,0) | E29: =C29*Inputs!C7/Inputs!C8 | F29: =D29-E29 | G29: =C29-F29 | H29: =G28+E29
B30: 27 | C30: =G29 | D30: =IF(27<=Inputs!C10*Inputs!C8,Inputs!C6/(Inputs!C10*Inputs!C8)+Inputs!C6*Inputs!C7/Inputs!C8,0) | E30: =C30*Inputs!C7/Inputs!C8 | F30: =D30-E30 | G30: =C30-F30 | H30: =G29+E30
B31: 28 | C31: =G30 | D31: =IF(28<=Inputs!C10*Inputs!C8,Inputs!C6/(Inputs!C10*Inputs!C8)+Inputs!C6*Inputs!C7/Inputs!C8,0) | E31: =C31*Inputs!C7/Inputs!C8 | F31: =D31-E31 | G31: =C31-F31 | H31: =G30+E31
B32: 29 | C32: =G31 | D32: =IF(29<=Inputs!C10*Inputs!C8,Inputs!C6/(Inputs!C10*Inputs!C8)+Inputs!C6*Inputs!C7/Inputs!C8,0) | E32: =C32*Inputs!C7/Inputs!C8 | F32: =D32-E32 | G32: =C32-F32 | H32: =G31+E32
B33: 30 | C33: =G32 | D33: =IF(30<=Inputs!C10*Inputs!C8,Inputs!C6/(Inputs!C10*Inputs!C8)+Inputs!C6*Inputs!C7/Inputs!C8,0) | E33: =C33*Inputs!C7/Inputs!C8 | F33: =D33-E33 | G33: =C33-F33 | H33: =G32+E33
B34: 31 | C34: =G33 | D34: =IF(31<=Inputs!C10*Inputs!C8,Inputs!C6/(Inputs!C10*Inputs!C8)+Inputs!C6*Inputs!C7/Inputs!C8,0) | E34: =C34*Inputs!C7/Inputs!C8 | F34: =D34-E34 | G34: =C34-F34 | H34: =G33+E34
B35: 32 | C35: =G34 | D35: =IF(32<=Inputs!C10*Inputs!C8,Inputs!C6/(Inputs!C10*Inputs!C8)+Inputs!C6*Inputs!C7/Inputs!C8,0) | E35: =C35*Inputs!C7/Inputs!C8 | F35: =D35-E35 | G35: =C35-F35 | H35: =G34+E35
B36: 33 | C36: =G35 | D36: =IF(33<=Inputs!C10*Inputs!C8,Inputs!C6/(Inputs!C10*Inputs!C8)+Inputs!C6*Inputs!C7/Inputs!C8,0) | E36: =C36*Inputs!C7/Inputs!C8 | F36: =D36-E36 | G36: =C36-F36 | H36: =G35+E36
B37: 34 | C37: =G36 | D37: =IF(34<=Inputs!C10*Inputs!C8,Inputs!C6/(Inputs!C10*Inputs!C8)+Inputs!C6*Inputs!C7/Inputs!C8,0) | E37: =C37*Inputs!C7/Inputs!C8 | F37: =D37-E37 | G37: =C37-F37 | H37: =G36+E37
B38: 35 | C38: =G37 | D38: =IF(35<=Inputs!C10*Inputs!C8,Inputs!C6/(Inputs!C10*Inputs!C8)+Inputs!C6*Inputs!C7/Inputs!C8,0) | E38: =C38*Inputs!C7/Inputs!C8 | F38: =D38-E38 | G38: =C38-F38 | H38: =G37+E38
B39: 36 | C39: =G38 | D39: =IF(36<=Inputs!C10*Inputs!C8,Inputs!C6/(Inputs!C10*Inputs!C8)+Inputs!C6*Inputs!C7/Inputs!C8,0) | E39: =C39*Inputs!C7/Inputs!C8 | F39: =D39-E39 | G39: =C39-F39 | H39: =G38+E39
B40: 37 | C40: =G39 | D40: =IF(37<=Inputs!C10*Inputs!C8,Inputs!C6/(Inputs!C10*Inputs!C8)+Inputs!C6*Inputs!C7/Inputs!C8,0) | E40: =C40*Inputs!C7/Inputs!C8 | F40: =D40-E40 | G40: =C40-F40 | H40: =G39+E40
B41: 38 | C41: =G40 | D41: =IF(38<=Inputs!C10*Inputs!C8,Inputs!C6/(Inputs!C10*Inputs!C8)+Inputs!C6*Inputs!C7/Inputs!C8,0) | E41: =C41*Inputs!C7/Inputs!C8 | F41: =D41-E41 | G41: =C41-F41 | H41: =G40+E41
...
